Workbook

Sheet Leiðbeiningar
B2: Launagreiningar-sniðmát
B3: Jafnréttisstofa • Skýrsluferli – Innsláttarskjal
B5: Flipaskipan
B6: Viðmið | C6: Yfirflokkarnir (starfsbundnir og einstaklingsbundnir). Vægi verður að summast í 100%. Aðeins eitt einstaklingsbundið viðmið er leyft. Vægi eru auð í upphafi og þarf að fylla út.
B7: Undirviðmið | C7: Undirflokkar hvers viðmiðs. Veldu yfirviðmið og undirviðmið úr fellilistum; skilgreining, fjöldi þrepa og þrepalýsingar fyllast sjálfkrafa út frá Undirviðmiðalistanum (aftasti flipi) en má yfirskrifa. Listinn hefur bæði starfsbundna og einstaklingsbundna hluta; frjáls texti er líka leyfður. Vægi undirviðmiða verður að summast í vægi yfirviðmiðsins.
B8: Starfsmenn | C8: Listi yfir starfsfólk með laun, menntun og starfsupplýsingar.
B9: Flokkun starfa | C9: Stigagjöf per starfsheiti (línur) á starfsbundnum (skylda) undirviðmiðum (dálkar).
B10: Flokkun starfsmanna | C10: Stigagjöf per starfsmann á einstaklingsbundnum (valfrjálsum) undirviðmiðum.
B11: Yfirlit | C11: Samantekt: heildarstig á starfsmann (starfsbundið + einstaklingsbundið) og launatölur.
B13: Reiknilíkan – Stigagjöf
B14: Formúla | C14: stig = (þrep / fjöldi þrepa) × vægi × KVARÐI
B15: KVARÐI | C15: Sjálfgefið 10 → hámark heildarstig = 1000 á starfsmann (100% × 10).
B16: Dæmi | C16: Undirviðmið með 10% vægi og 5 þrepum: hámark = 100 stig, þrep 3 = 60 stig.
B17: Dæmi 2 | C17: Undirviðmið með 5% vægi og 5 þrepum: hámark = 50 stig, þrep 3 = 30 stig.
B19: Litakóðun
B20: Blátt letur | C20: Innsláttarreitir (notandi fyllir út).
B21: Svart letur | C21: Reiknaðir reitir (formúlur) – má ekki breyta.
B22: Grænt letur | C22: Tilvísanir í aðra flipa – má ekki breyta.
B23: Grár bakgrunnur | C23: Læstir reitir (t.d. lögboðnir flokkar sem ekki má endurnefna).
B24: Gulur bakgrunnur | C24: Reitir sem þurfa athygli eða eru sjálfvirkir villuvísar.
B25: Rauður bakgrunnur | C25: Villa – t.d. vægi summast ekki í 100%.
B27: Valideringsreglur
B28: Viðmið | C28: Summa vægis (starfsbundið + einstaklingsbundið) = nákvæmlega 100%.
B29: Undirviðmið | C29: Summa vægis undirviðmiða innan hvers yfirviðmiðs = vægi þess yfirviðmiðs.
B30: Þrep | C30: Aðeins heilar tölur 1…fjöldi_þrepa eru leyfðar.
B31: Starfshlutfall | C31: Gildi á bilinu 0–1 með aukastöfum: 1 = 100%, 0,55 = 55%. Gildið er geymt beint sem hlutfall (0–1) og samsvarar gagnagrunnsreitnum án umreiknings.
B32: Aukagreiðslur | C32: Má vera autt ef á ekki við — gagnagrunnsreiturinn er valfrjáls (nullable).
B33: Ráðningardagur | C33: Ein dagsetning (d.m.yyyy) — ekki tímabil. Samsvarar 'start_date' í gagnagrunni.
B34: Uppreiknuð laun v/ 100% starfshlutfall | C34: Tveir síðustu dálkar á Starfsmenn og Yfirlit reiknast sjálfvirkt út frá starfshlutfalli (0–1): Grunnlaun / starfshlutfall, og (Grunnlaun + Viðbótarlaun + Aukagreiðslur) / starfshlutfall. Þetta gefur samanburðarhæfa tölu óháð því hvort starfsmaðurinn er í fullu starfi eða hlutastarfi. Reitirnir eru læstir.
B36: Persónugreinanleg gögn
B37: Nafn | C37: Nafn er eingöngu til hægðarauka á þessu skjali. Það er EKKI sent til Jafnréttisstofu — gagnagrunnurinn geymir aðeins raðnúmer (ordinal) sem auðkenni starfsmanns.
B38: Kennitala | C38: Kennitala er ekki skráð í skjalið — kerfið býr til tímabundið auðkenni sjálfvirkt við innsendingu.
B40: Notkun
B41: 1 | C41: Fylltu út viðmið og stilltu vægi á Viðmið flipanum.
B42: 2 | C42: Skráðu undirviðmið með vægi, þrepafjölda og lýsingum á Undirviðmið flipanum.
B43: 3 | C43: Skráðu starfsmenn á Starfsmenn flipanum.
B44: 4 | C44: Gefðu hverju starfsheiti þrep á Flokkun starfa.
B45: 5 | C45: Gefðu hverjum starfsmanni þrep á einstaklingsbundnum undirviðmiðum á Flokkun starfsmanna.
B46: 6 | C46: Skoðaðu niðurstöður á Yfirlit flipanum.
B48: KVARÐI (stillanlegt): | C48: 10
...

Sheet Viðmið
B2: Viðmið
B3: Skilgreindu viðmið og stilltu vægi. Heildarvægi allra viðmiða (bæði starfsbundinn og einstaklingsbundinn þáttur) þarf að summast í 100%. Aðeins má skilgreina eitt einstaklingsbundið viðmið.
B5: Tegund | C5: Viðmið | D5: Lýsing | E5: Vægi (%) | F5: Læst?
B6: Starfsbundið | C6: Ábyrgð | D6: Metur ábyrgð starfsins á fólki, fjármálum, gæðum og öðrum þáttum. | F6: Já
B7: Starfsbundið | C7: Álag | D7: Metur hraða, tímapressu, líkamlegt og tilfinningalegt álag. | F7: Já
B8: Starfsbundið | C8: Vinnuaðstæður | D8: Metur vaktavinnu, ferðalög, áhættu og aðrar aðstæður starfsins. | F8: Já
B9: Starfsbundið | C9: Hæfni | D9: Metur menntunarkröfur, reynslukröfur og sérhæfingu starfsins. | F9: Já
B10: Einstaklingsbundið | F10: Nei
D12: Heildarvægi: | E12: =SUM(E6:E10) -> 0 | F12: =IF(ROUND(E12,4)=100,"✓ OK","✗ Þarf 100%") -> ✗ Þarf 100%
D13: Fjöldi einstaklingsbundinna viðmiða: | E13: =COUNTIF(B6:B10,"Einstaklingsbundið") -> 1 | F13: =IF(E13<=1,"✓ OK","✗ Hámark er 1") -> ✓ OK

Sheet Undirviðmið
B2: Undirviðmið
B3: Veldu yfirviðmið og undirviðmið úr fellilistum. Skilgreining, fjöldi þrepa og þrepalýsingar fyllast sjálfkrafa út frá Undirviðmiðalistanum (aftasti flipi) en má yfirskrifa. Listinn inniheldur bæði starfsbundin og einstaklingsbundin undirviðmið; einnig má skrá undirviðmið sem frjálsan texta. Ef fjöldi þrepa fyllist ekki sjálfkrafa þarf að skrá hann handvirkt (2–8). Sláðu inn vægi (%) fyrir hvert undirviðmið; vægi allra undirviðmiða undir sama yfirviðmiði verður að jafngilda vægi þess.
A5: # | B5: Yfirviðmið | C5: Undirviðmið | D5: Skilgreining | E5: Vægi (%) | F5: Fjöldi þrepa | G5: Tegund (sjálfvirkt) | H5: Hámarksstig | I5: Samsumma OK? | J5: Þrep 1 | K5: Þrep 2 | L5: Þrep 3 | M5: Þrep 4 | N5: Þrep 5 | O5: Þrep 6 | P5: Þrep 7 | Q5: Þrep 8
A6: =IF($B6="","",ROW()-5) | D6: =IF($C6="","",IF($G6="Einstaklingsbundið",IFERROR(IF(INDEX('Undirviðmiðalisti (Lýsigögn)'!$D$42:$D$58,MATCH($C6,'Undirviðmiðalisti (Lýsigögn)'!$C$42:$C$58,0))="","",INDEX('Undirviðmiðalisti (Lýsigögn)'!$D$42:$D$58,MATCH($C6,'Undirviðmiðalisti (Lýsigögn)'!$C$42:$C$58,0))),""),IFERROR(IF(INDEX('Undirviðmiðalisti (Lýsigögn)'!$D$6:$D$41,MATCH($C6,'Undirviðmiðalisti (Lýsigögn)'!$C$6:$C$41,0))="","",INDEX('Undirviðmiðalisti (Lýsigögn)'!$D$6:$D$41,MATCH($C6,'Undirviðmiðalisti (Lýsigögn)'!$C$6:$C$41,0))),IFERROR(IF(INDEX('Undirviðmiðalisti (Lýsigögn)'!$D$42:$D$58,MATCH($C6,'Undirviðmiðalisti (Lýsigögn)'!$C$42:$C$58,0))="","",INDEX('Undirviðmiðalisti (Lýsigögn)'!$D$42:$D$58,MATCH($C6,'Undirviðmiðalisti (Lýsigögn)'!$C$42:$C$58,0))),"")))) | F6: =IF($C6="","",IF($G6="Einstaklingsbundið",IFERROR(IF(INDEX('Undirviðmiðalisti (Lýsigögn)'!$E$42:$E$58,MATCH($C6,'Undirviðmiðalisti (Lýsigögn)'!$C$42:$C$58,0))="","",INDEX('Undirviðmiðalisti (Lýsigögn)'!$E$42:$E$58,MATCH($C6,'Undirviðmiðalisti (Lýsigögn)'!$C$42:$C$58,0))),""),IFERROR(IF(INDEX('Undirviðmiðalisti (Lýsigögn)'!$E$6:$E$41,MATCH($C6,'Undirviðmiðalisti (Lýsigögn)'!$C$6:$C$41,0))="","",INDEX('Undirviðmiðalisti (Lýsigögn)'!$E$6:$E$41,MATCH($C6,'Undirviðmiðalisti (Lýsigögn)'!$C$6:$C$41,0))),IFERROR(IF(INDEX('Undirviðmiðalisti (Lýsigögn)'!$E$42:$E$58,MATCH($C6,'Undirviðmiðalisti (Lýsigögn)'!$C$42:$C$58,0))="","",INDEX('Undirviðmiðalisti (Lýsigögn)'!$E$42:$E$58,MATCH($C6,'Undirviðmiðalisti (Lýsigögn)'!$C$42:$C$58,0))),"")))) | G6: =IFERROR(IF(B6="","",INDEX(Viðmið!$B$6:$B$10,MATCH(B6,Viðmið!$C$6:$C$10,0))),"") | H6: =IF(OR(E6="",F6=""),"",E6*KVARDI) | I6: =IF(B6="","",IF(ROUND(SUMIF($B$6:$B$205,B6,$E$6:$E$205),4)=ROUND(IFERROR(INDEX(Viðmið!$E$6:$E$10,MATCH(B6,Viðmið!$C$6:$C$10,0)),-1),4),"✓","✗")) | J6: =IF($C6="","",IF($G6="Einstaklingsbundið",IFERROR(IF(INDEX('Undirviðmiðalisti (Lýsigögn)'!F$42:F$58,MATCH($C6,'Undirviðmiðalisti (Lýsigögn)'!$C$42:$C$58,0))="","",INDEX('Undirviðmiðalisti (Lýsigögn)'!F$42:F$58,MATCH($C6,'Undirviðmiðalisti (Lýsigögn)'!$C$42:$C$58,0))),""),IFERROR(IF(INDEX('Undirviðmiðalisti (Lýsigögn)'!F$6:F$41,MATCH($C6,'Undirviðmiðalisti (Lýsigögn)'!$C$6:$C$41,0))="","",INDEX('Undirviðmiðalisti (Lýsigögn)'!F$6:F$41,MATCH($C6,'Undirviðmiðalisti (Lýsigögn)'!$C$6:$C$41,0))),IFERROR(IF(INDEX('Undirviðmiðalisti (Lýsigögn)'!F$42:F$58,MATCH($C6,'Undirviðmiðalisti (Lýsigögn)'!$C$42:$C$58,0))="","",INDEX('Undirviðmiðalisti (Lýsigögn)'!F$42:F$58,MATCH($C6,'Undirviðmiðalisti (Lýsigögn)'!$C$42:$C$58,0))),"")))) | K6: =IF($C6="","",IF($G6="Einstaklingsbundið",IFERROR(IF(INDEX('Undirviðmiðalisti (Lýsigögn)'!G$42:G$58,MATCH($C6,'Undirviðmiðalisti (Lýsigögn)'!$C$42:$C$58,0))="","",INDEX('Undirviðmiðalisti (Lýsigögn)'!G$42:G$58,MATCH($C6,'Undirviðmiðalisti (Lýsigögn)'!$C$42:$C$58,0))),""),IFERROR(IF(INDEX('Undirviðmiðalisti (Lýsigögn)'!G$6:G$41,MATCH($C6,'Undirviðmiðalisti (Lýsigögn)'!$C$6:$C$41,0))="","",INDEX('Undirviðmiðalisti (Lýsigögn)'!G$6:G$41,MATCH($C6,'Undirviðmiðalisti (Lýsigögn)'!$C$6:$C$41,0))),IFERROR(IF(INDEX('Undirviðmiðalisti (Lýsigögn)'!G$42:G$58,MATCH($C6,'Undirviðmiðalisti (Lýsigögn)'!$C$42:$C$58,0))="","",INDEX('Undirviðmiðalisti (Lýsigögn)'!G$42:G$58,MATCH($C6,'Undirviðmiðalisti (Lýsigögn)'!$C$42:$C$58,0))),"")))) | L6: =IF($C6="","",IF($G6="Einstaklingsbundið",IFERROR(IF(INDEX('Undirviðmiðalisti (Lýsigögn)'!H$42:H$58,MATCH($C6,'Undirviðmiðalisti (Lýsigögn)'!$C$42:$C$58,0))="","",INDEX('Undirviðmiðalisti (Lýsigögn)'!H$42:H$58,MATCH($C6,'Undirviðmiðalisti (Lýsigögn)'!$C$42:$C$58,0))),""),IFERROR(IF(INDEX('Undirviðmiðalisti (Lýsigögn)'!H$6:H$41,MATCH($C6,'Undirviðmiðalisti (Lýsigögn)'!$C$6:$C$41,0))="","",INDEX('Undirviðmiðalisti (Lýsigögn)'!H$6:H$41,MATCH($C6,'Undirviðmiðalisti (Lýsigögn)'!$C$6:$C$41,0))),IFERROR(IF(INDEX('Undirviðmiðalisti (Lýsigögn)'!H$42:H$58,MATCH($C6,'Undirviðmiðalisti (Lýsigögn)'!$C$42:$C$58,0))="","",INDEX('Undirviðmiðalisti (Lýsigögn)'!H$42:H$58,MATCH($C6,'Undirviðmiðalisti (Lýsigögn)'!$C$42:$C$58,0))),"")))) | M6: =IF($C6="","",IF($G6="Einstaklingsbundið",IFERROR(IF(INDEX('Undirviðmiðalisti (Lýsigögn)'!I$42:I$58,MATCH($C6,'Undirviðmiðalisti (Lýsigögn)'!$C$42:$C$58,0))="","",INDEX('Undirviðmiðalisti (Lýsigögn)'!I$42:I$58,MATCH($C6,'Undirviðmiðalisti (Lýsigögn)'!$C$42:$C$58,0))),""),IFERROR(IF(INDEX('Undirviðmiðalisti (Lýsigögn)'!I$6:I$41,MATCH($C6,'Undirviðmiðalisti (Lýsigögn)'!$C$6:$C$41,0))="","",INDEX('Undirviðmiðalisti (Lýsigögn)'!I$6:I$41,MATCH($C6,'Undirviðmiðalisti (Lýsigögn)'!$C$6:$C$41,0))),IFERROR(IF(INDEX('Undirviðmiðalisti (Lýsigögn)'!I$42:I$58,MATCH($C6,'Undirviðmiðalisti (Lýsigögn)'!$C$42:$C$58,0))="","",INDEX('Undirviðmiðalisti (Lýsigögn)'!I$42:I$58,MATCH($C6,'Undirviðmiðalisti (Lýsigögn)'!$C$42:$C$58,0))),"")))) | N6: =IF($C6="","",IF($G6="Einstaklingsbundið",IFERROR(IF(INDEX('Undirviðmiðalisti (Lýsigögn)'!J$42:J$58,MATCH($C6,'Undirviðmiðalisti (Lýsigögn)'!$C$42:$C$58,0))="","",INDEX('Undirviðmiðalisti (Lýsigögn)'!J$42:J$58,MATCH($C6,'Undirviðmiðalisti (Lýsigögn)'!$C$42:$C$58,0))),""),IFERROR(IF(INDEX('Undirviðmiðalisti (Lýsigögn)'!J$6:J$41,MATCH($C6,'Undirviðmiðalisti (Lýsigögn)'!$C$6:$C$41,0))="","",INDEX('Undirviðmiðalisti (Lýsigögn)'!J$6:J$41,MATCH($C6,'Undirviðmiðalisti (Lýsigögn)'!$C$6:$C$41,0))),IFERROR(IF(INDEX('Undirviðmiðalisti (Lýsigögn)'!J$42:J$58,MATCH($C6,'Undirviðmiðalisti (Lýsigögn)'!$C$42:$C$58,0))="","",INDEX('Undirviðmiðalisti (Lýsigögn)'!J$42:J$58,MATCH($C6,'Undirviðmiðalisti (Lýsigögn)'!$C$42:$C$58,0))),"")))) | O6: =IF($C6="","",IF($G6="Einstaklingsbundið",IFERROR(IF(INDEX('Undirviðmiðalisti (Lýsigögn)'!K$42:K$58,MATCH($C6,'Undirviðmiðalisti (Lýsigögn)'!$C$42:$C$58,0))="","",INDEX('Undirviðmiðalisti (Lýsigögn)'!K$42:K$58,MATCH($C6,'Undirviðmiðalisti (Lýsigögn)'!$C$42:$C$58,0))),""),IFERROR(IF(INDEX('Undirviðmiðalisti (Lýsigögn)'!K$6:K$41,MATCH($C6,'Undirviðmiðalisti (Lýsigögn)'!$C$6:$C$41,0))="","",INDEX('Undirviðmiðalisti (Lýsigögn)'!K$6:K$41,MATCH($C6,'Undirviðmiðalisti (Lýsigögn)'!$C$6:$C$41,0))),IFERROR(IF(INDEX('Undirviðmiðalisti (Lýsigögn)'!K$42:K$58,MATCH($C6,'Undirviðmiðalisti (Lýsigögn)'!$C$42:$C$58,0))="","",INDEX('Undirviðmiðalisti (Lýsigögn)'!K$42:K$58,MATCH($C6,'Undirviðmiðalisti (Lýsigögn)'!$C$42:$C$58,0))),"")))) | P6: =IF($C6="","",IF($G6="Einstaklingsbundið",IFERROR(IF(INDEX('Undirviðmiðalisti (Lýsigögn)'!L$42:L$58,MATCH($C6,'Undirviðmiðalisti (Lýsigögn)'!$C$42:$C$58,0))="","",INDEX('Undirviðmiðalisti (Lýsigögn)'!L$42:L$58,MATCH($C6,'Undirviðmiðalisti (Lýsigögn)'!$C$42:$C$58,0))),""),IFERROR(IF(INDEX('Undirviðmiðalisti (Lýsigögn)'!L$6:L$41,MATCH($C6,'Undirviðmiðalisti (Lýsigögn)'!$C$6:$C$41,0))="","",INDEX('Undirviðmiðalisti (Lýsigögn)'!L$6:L$41,MATCH($C6,'Undirviðmiðalisti (Lýsigögn)'!$C$6:$C$41,0))),IFERROR(IF(INDEX('Undirviðmiðalisti (Lýsigögn)'!L$42:L$58,MATCH($C6,'Undirviðmiðalisti (Lýsigögn)'!$C$42:$C$58,0))="","",INDEX('Undirviðmiðalisti (Lýsigögn)'!L$42:L$58,MATCH($C6,'Undirviðmiðalisti (Lýsigögn)'!$C$42:$C$58,0))),"")))) | Q6: =IF($C6="","",IF($G6="Einstaklingsbundið",IFERROR(IF(INDEX('Undirviðmiðalisti (Lýsigögn)'!M$42:M$58,MATCH($C6,'Undirviðmiðalisti (Lýsigögn)'!$C$42:$C$58,0))="","",INDEX('Undirviðmiðalisti (Lýsigögn)'!M$42:M$58,MATCH($C6,'Undirviðmiðalisti (Lýsigögn)'!$C$42:$C$58,0))),""),IFERROR(IF(INDEX('Undirviðmiðalisti (Lýsigögn)'!M$6:M$41,MATCH($C6,'Undirviðmiðalisti (Lýsigögn)'!$C$6:$C$41,0))="","",INDEX('Undirviðmiðalisti (Lýsigögn)'!M$6:M$41,MATCH($C6,'Undirviðmiðalisti (Lýsigögn)'!$C$6:$C$41,0))),IFERROR(IF(INDEX('Undirviðmiðalisti (Lýsigögn)'!M$42:M$58,MATCH($C6,'Undirviðmiðalisti (Lýsigögn)'!$C$42:$C$58,0))="","",INDEX('Undirviðmiðalisti (Lýsigögn)'!M$42:M$58,MATCH($C6,'Undirviðmiðalisti (Lýsigögn)'!$C$42:$C$58,0))),""))))
A7: =IF($B7="","",ROW()-5) | D7: =IF($C7="","",IF($G7="Einstaklingsbundið",IFERROR(IF(INDEX('Undirviðmiðalisti (Lýsigögn)'!$D$42:$D$58,MATCH($C7,'Undirviðmiðalisti (Lýsigögn)'!$C$42:$C$58,0))="","",INDEX('Undirviðmiðalisti (Lýsigögn)'!$D$42:$D$58,MATCH($C7,'Undirviðmiðalisti (Lýsigögn)'!$C$42:$C$58,0))),""),IFERROR(IF(INDEX('Undirviðmiðalisti (Lýsigögn)'!$D$6:$D$41,MATCH($C7,'Undirviðmiðalisti (Lýsigögn)'!$C$6:$C$41,0))="","",INDEX('Undirviðmiðalisti (Lýsigögn)'!$D$6:$D$41,MATCH($C7,'Undirviðmiðalisti (Lýsigögn)'!$C$6:$C$41,0))),IFERROR(IF(INDEX('Undirviðmiðalisti (Lýsigögn)'!$D$42:$D$58,MATCH($C7,'Undirviðmiðalisti (Lýsigögn)'!$C$42:$C$58,0))="","",INDEX('Undirviðmiðalisti (Lýsigögn)'!$D$42:$D$58,MATCH($C7,'Undirviðmiðalisti (Lýsigögn)'!$C$42:$C$58,0))),"")))) | F7: =IF($C7="","",IF($G7="Einstaklingsbundið",IFERROR(IF(INDEX('Undirviðmiðalisti (Lýsigögn)'!$E$42:$E$58,MATCH($C7,'Undirviðmiðalisti (Lýsigögn)'!$C$42:$C$58,0))="","",INDEX('Undirviðmiðalisti (Lýsigögn)'!$E$42:$E$58,MATCH($C7,'Undirviðmiðalisti (Lýsigögn)'!$C$42:$C$58,0))),""),IFERROR(IF(INDEX('Undirviðmiðalisti (Lýsigögn)'!$E$6:$E$41,MATCH($C7,'Undirviðmiðalisti (Lýsigögn)'!$C$6:$C$41,0))="","",INDEX('Undirviðmiðalisti (Lýsigögn)'!$E$6:$E$41,MATCH($C7,'Undirviðmiðalisti (Lýsigögn)'!$C$6:$C$41,0))),IFERROR(IF(INDEX('Undirviðmiðalisti (Lýsigögn)'!$E$42:$E$58,MATCH($C7,'Undirviðmiðalisti (Lýsigögn)'!$C$42:$C$58,0))="","",INDEX('Undirviðmiðalisti (Lýsigögn)'!$E$42:$E$58,MATCH($C7,'Undirviðmiðalisti (Lýsigögn)'!$C$42:$C$58,0))),"")))) | G7: =IFERROR(IF(B7="","",INDEX(Viðmið!$B$6:$B$10,MATCH(B7,Viðmið!$C$6:$C$10,0))),"") | H7: =IF(OR(E7="",F7=""),"",E7*KVARDI) | I7: =IF(B7="","",IF(ROUND(SUMIF($B$6:$B$205,B7,$E$6:$E$205),4)=ROUND(IFERROR(INDEX(Viðmið!$E$6:$E$10,MATCH(B7,Viðmið!$C$6:$C$10,0)),-1),4),"✓","✗")) | J7: =IF($C7="","",IF($G7="Einstaklingsbundið",IFERROR(IF(INDEX('Undirviðmiðalisti (Lýsigögn)'!F$42:F$58,MATCH($C7,'Undirviðmiðalisti (Lýsigögn)'!$C$42:$C$58,0))="","",INDEX('Undirviðmiðalisti (Lýsigögn)'!F$42:F$58,MATCH($C7,'Undirviðmiðalisti (Lýsigögn)'!$C$42:$C$58,0))),""),IFERROR(IF(INDEX('Undirviðmiðalisti (Lýsigögn)'!F$6:F$41,MATCH($C7,'Undirviðmiðalisti (Lýsigögn)'!$C$6:$C$41,0))="","",INDEX('Undirviðmiðalisti (Lýsigögn)'!F$6:F$41,MATCH($C7,'Undirviðmiðalisti (Lýsigögn)'!$C$6:$C$41,0))),IFERROR(IF(INDEX('Undirviðmiðalisti (Lýsigögn)'!F$42:F$58,MATCH($C7,'Undirviðmiðalisti (Lýsigögn)'!$C$42:$C$58,0))="","",INDEX('Undirviðmiðalisti (Lýsigögn)'!F$42:F$58,MATCH($C7,'Undirviðmiðalisti (Lýsigögn)'!$C$42:$C$58,0))),"")))) | K7: =IF($C7="","",IF($G7="Einstaklingsbundið",IFERROR(IF(INDEX('Undirviðmiðalisti (Lýsigögn)'!G$42:G$58,MATCH($C7,'Undirviðmiðalisti (Lýsigögn)'!$C$42:$C$58,0))="","",INDEX('Undirviðmiðalisti (Lýsigögn)'!G$42:G$58,MATCH($C7,'Undirviðmiðalisti (Lýsigögn)'!$C$42:$C$58,0))),""),IFERROR(IF(INDEX('Undirviðmiðalisti (Lýsigögn)'!G$6:G$41,MATCH($C7,'Undirviðmiðalisti (Lýsigögn)'!$C$6:$C$41,0))="","",INDEX('Undirviðmiðalisti (Lýsigögn)'!G$6:G$41,MATCH($C7,'Undirviðmiðalisti (Lýsigögn)'!$C$6:$C$41,0))),IFERROR(IF(INDEX('Undirviðmiðalisti (Lýsigögn)'!G$42:G$58,MATCH($C7,'Undirviðmiðalisti (Lýsigögn)'!$C$42:$C$58,0))="","",INDEX('Undirviðmiðalisti (Lýsigögn)'!G$42:G$58,MATCH($C7,'Undirviðmiðalisti (Lýsigögn)'!$C$42:$C$58,0))),"")))) | L7: =IF($C7="","",IF($G7="Einstaklingsbundið",IFERROR(IF(INDEX('Undirviðmiðalisti (Lýsigögn)'!H$42:H$58,MATCH($C7,'Undirviðmiðalisti (Lýsigögn)'!$C$42:$C$58,0))="","",INDEX('Undirviðmiðalisti (Lýsigögn)'!H$42:H$58,MATCH($C7,'Undirviðmiðalisti (Lýsigögn)'!$C$42:$C$58,0))),""),IFERROR(IF(INDEX('Undirviðmiðalisti (Lýsigögn)'!H$6:H$41,MATCH($C7,'Undirviðmiðalisti (Lýsigögn)'!$C$6:$C$41,0))="","",INDEX('Undirviðmiðalisti (Lýsigögn)'!H$6:H$41,MATCH($C7,'Undirviðmiðalisti (Lýsigögn)'!$C$6:$C$41,0))),IFERROR(IF(INDEX('Undirviðmiðalisti (Lýsigögn)'!H$42:H$58,MATCH($C7,'Undirviðmiðalisti (Lýsigögn)'!$C$42:$C$58,0))="","",INDEX('Undirviðmiðalisti (Lýsigögn)'!H$42:H$58,MATCH($C7,'Undirviðmiðalisti (Lýsigögn)'!$C$42:$C$58,0))),"")))) | M7: =IF($C7="","",IF($G7="Einstaklingsbundið",IFERROR(IF(INDEX('Undirviðmiðalisti (Lýsigögn)'!I$42:I$58,MATCH($C7,'Undirviðmiðalisti (Lýsigögn)'!$C$42:$C$58,0))="","",INDEX('Undirviðmiðalisti (Lýsigögn)'!I$42:I$58,MATCH($C7,'Undirviðmiðalisti (Lýsigögn)'!$C$42:$C$58,0))),""),IFERROR(IF(INDEX('Undirviðmiðalisti (Lýsigögn)'!I$6:I$41,MATCH($C7,'Undirviðmiðalisti (Lýsigögn)'!$C$6:$C$41,0))="","",INDEX('Undirviðmiðalisti (Lýsigögn)'!I$6:I$41,MATCH($C7,'Undirviðmiðalisti (Lýsigögn)'!$C$6:$C$41,0))),IFERROR(IF(INDEX('Undirviðmiðalisti (Lýsigögn)'!I$42:I$58,MATCH($C7,'Undirviðmiðalisti (Lýsigögn)'!$C$42:$C$58,0))="","",INDEX('Undirviðmiðalisti (Lýsigögn)'!I$42:I$58,MATCH($C7,'Undirviðmiðalisti (Lýsigögn)'!$C$42:$C$58,0))),"")))) | N7: =IF($C7="","",IF($G7="Einstaklingsbundið",IFERROR(IF(INDEX('Undirviðmiðalisti (Lýsigögn)'!J$42:J$58,MATCH($C7,'Undirviðmiðalisti (Lýsigögn)'!$C$42:$C$58,0))="","",INDEX('Undirviðmiðalisti (Lýsigögn)'!J$42:J$58,MATCH($C7,'Undirviðmiðalisti (Lýsigögn)'!$C$42:$C$58,0))),""),IFERROR(IF(INDEX('Undirviðmiðalisti (Lýsigögn)'!J$6:J$41,MATCH($C7,'Undirviðmiðalisti (Lýsigögn)'!$C$6:$C$41,0))="","",INDEX('Undirviðmiðalisti (Lýsigögn)'!J$6:J$41,MATCH($C7,'Undirviðmiðalisti (Lýsigögn)'!$C$6:$C$41,0))),IFERROR(IF(INDEX('Undirviðmiðalisti (Lýsigögn)'!J$42:J$58,MATCH($C7,'Undirviðmiðalisti (Lýsigögn)'!$C$42:$C$58,0))="","",INDEX('Undirviðmiðalisti (Lýsigögn)'!J$42:J$58,MATCH($C7,'Undirviðmiðalisti (Lýsigögn)'!$C$42:$C$58,0))),"")))) | O7: =IF($C7="","",IF($G7="Einstaklingsbundið",IFERROR(IF(INDEX('Undirviðmiðalisti (Lýsigögn)'!K$42:K$58,MATCH($C7,'Undirviðmiðalisti (Lýsigögn)'!$C$42:$C$58,0))="","",INDEX('Undirviðmiðalisti (Lýsigögn)'!K$42:K$58,MATCH($C7,'Undirviðmiðalisti (Lýsigögn)'!$C$42:$C$58,0))),""),IFERROR(IF(INDEX('Undirviðmiðalisti (Lýsigögn)'!K$6:K$41,MATCH($C7,'Undirviðmiðalisti (Lýsigögn)'!$C$6:$C$41,0))="","",INDEX('Undirviðmiðalisti (Lýsigögn)'!K$6:K$41,MATCH($C7,'Undirviðmiðalisti (Lýsigögn)'!$C$6:$C$41,0))),IFERROR(IF(INDEX('Undirviðmiðalisti (Lýsigögn)'!K$42:K$58,MATCH($C7,'Undirviðmiðalisti (Lýsigögn)'!$C$42:$C$58,0))="","",INDEX('Undirviðmiðalisti (Lýsigögn)'!K$42:K$58,MATCH($C7,'Undirviðmiðalisti (Lýsigögn)'!$C$42:$C$58,0))),"")))) | P7: =IF($C7="","",IF($G7="Einstaklingsbundið",IFERROR(IF(INDEX('Undirviðmiðalisti (Lýsigögn)'!L$42:L$58,MATCH($C7,'Undirviðmiðalisti (Lýsigögn)'!$C$42:$C$58,0))="","",INDEX('Undirviðmiðalisti (Lýsigögn)'!L$42:L$58,MATCH($C7,'Undirviðmiðalisti (Lýsigögn)'!$C$42:$C$58,0))),""),IFERROR(IF(INDEX('Undirviðmiðalisti (Lýsigögn)'!L$6:L$41,MATCH($C7,'Undirviðmiðalisti (Lýsigögn)'!$C$6:$C$41,0))="","",INDEX('Undirviðmiðalisti (Lýsigögn)'!L$6:L$41,MATCH($C7,'Undirviðmiðalisti (Lýsigögn)'!$C$6:$C$41,0))),IFERROR(IF(INDEX('Undirviðmiðalisti (Lýsigögn)'!L$42:L$58,MATCH($C7,'Undirviðmiðalisti (Lýsigögn)'!$C$42:$C$58,0))="","",INDEX('Undirviðmiðalisti (Lýsigögn)'!L$42:L$58,MATCH($C7,'Undirviðmiðalisti (Lýsigögn)'!$C$42:$C$58,0))),"")))) | Q7: =IF($C7="","",IF($G7="Einstaklingsbundið",IFERROR(IF(INDEX('Undirviðmiðalisti (Lýsigögn)'!M$42:M$58,MATCH($C7,'Undirviðmiðalisti (Lýsigögn)'!$C$42:$C$58,0))="","",INDEX('Undirviðmiðalisti (Lýsigögn)'!M$42:M$58,MATCH($C7,'Undirviðmiðalisti (Lýsigögn)'!$C$42:$C$58,0))),""),IFERROR(IF(INDEX('Undirviðmiðalisti (Lýsigögn)'!M$6:M$41,MATCH($C7,'Undirviðmiðalisti (Lýsigögn)'!$C$6:$C$41,0))="","",INDEX('Undirviðmiðalisti (Lýsigögn)'!M$6:M$41,MATCH($C7,'Undirviðmiðalisti (Lýsigögn)'!$C$6:$C$41,0))),IFERROR(IF(INDEX('Undirviðmiðalisti (Lýsigögn)'!M$42:M$58,MATCH($C7,'Undirviðmiðalisti (Lýsigögn)'!$C$42:$C$58,0))="","",INDEX('Undirviðmiðalisti (Lýsigögn)'!M$42:M$58,MATCH($C7,'Undirviðmiðalisti (Lýsigögn)'!$C$42:$C$58,0))),""))))
A8: =IF($B8="","",ROW()-5) | D8: =IF($C8="","",IF($G8="Einstaklingsbundið",IFERROR(IF(INDEX('Undirviðmiðalisti (Lýsigögn)'!$D$42:$D$58,MATCH($C8,'Undirviðmiðalisti (Lýsigögn)'!$C$42:$C$58,0))="","",INDEX('Undirviðmiðalisti (Lýsigögn)'!$D$42:$D$58,MATCH($C8,'Undirviðmiðalisti (Lýsigögn)'!$C$42:$C$58,0))),""),IFERROR(IF(INDEX('Undirviðmiðalisti (Lýsigögn)'!$D$6:$D$41,MATCH($C8,'Undirviðmiðalisti (Lýsigögn)'!$C$6:$C$41,0))="","",INDEX('Undirviðmiðalisti (Lýsigögn)'!$D$6:$D$41,MATCH($C8,'Undirviðmiðalisti (Lýsigögn)'!$C$6:$C$41,0))),IFERROR(IF(INDEX('Undirviðmiðalisti (Lýsigögn)'!$D$42:$D$58,MATCH($C8,'Undirviðmiðalisti (Lýsigögn)'!$C$42:$C$58,0))="","",INDEX('Undirviðmiðalisti (Lýsigögn)'!$D$42:$D$58,MATCH($C8,'Undirviðmiðalisti (Lýsigögn)'!$C$42:$C$58,0))),"")))) | F8: =IF($C8="","",IF($G8="Einstaklingsbundið",IFERROR(IF(INDEX('Undirviðmiðalisti (Lýsigögn)'!$E$42:$E$58,MATCH($C8,'Undirviðmiðalisti (Lýsigögn)'!$C$42:$C$58,0))="","",INDEX('Undirviðmiðalisti (Lýsigögn)'!$E$42:$E$58,MATCH($C8,'Undirviðmiðalisti (Lýsigögn)'!$C$42:$C$58,0))),""),IFERROR(IF(INDEX('Undirviðmiðalisti (Lýsigögn)'!$E$6:$E$41,MATCH($C8,'Undirviðmiðalisti (Lýsigögn)'!$C$6:$C$41,0))="","",INDEX('Undirviðmiðalisti (Lýsigögn)'!$E$6:$E$41,MATCH($C8,'Undirviðmiðalisti (Lýsigögn)'!$C$6:$C$41,0))),IFERROR(IF(INDEX('Undirviðmiðalisti (Lýsigögn)'!$E$42:$E$58,MATCH($C8,'Undirviðmiðalisti (Lýsigögn)'!$C$42:$C$58,0))="","",INDEX('Undirviðmiðalisti (Lýsigögn)'!$E$42:$E$58,MATCH($C8,'Undirviðmiðalisti (Lýsigögn)'!$C$42:$C$58,0))),"")))) | G8: =IFERROR(IF(B8="","",INDEX(Viðmið!$B$6:$B$10,MATCH(B8,Viðmið!$C$6:$C$10,0))),"") | H8: =IF(OR(E8="",F8=""),"",E8*KVARDI) | I8: =IF(B8="","",IF(ROUND(SUMIF($B$6:$B$205,B8,$E$6:$E$205),4)=ROUND(IFERROR(INDEX(Viðmið!$E$6:$E$10,MATCH(B8,Viðmið!$C$6:$C$10,0)),-1),4),"✓","✗")) | J8: =IF($C8="","",IF($G8="Einstaklingsbundið",IFERROR(IF(INDEX('Undirviðmiðalisti (Lýsigögn)'!F$42:F$58,MATCH($C8,'Undirviðmiðalisti (Lýsigögn)'!$C$42:$C$58,0))="","",INDEX('Undirviðmiðalisti (Lýsigögn)'!F$42:F$58,MATCH($C8,'Undirviðmiðalisti (Lýsigögn)'!$C$42:$C$58,0))),""),IFERROR(IF(INDEX('Undirviðmiðalisti (Lýsigögn)'!F$6:F$41,MATCH($C8,'Undirviðmiðalisti (Lýsigögn)'!$C$6:$C$41,0))="","",INDEX('Undirviðmiðalisti (Lýsigögn)'!F$6:F$41,MATCH($C8,'Undirviðmiðalisti (Lýsigögn)'!$C$6:$C$41,0))),IFERROR(IF(INDEX('Undirviðmiðalisti (Lýsigögn)'!F$42:F$58,MATCH($C8,'Undirviðmiðalisti (Lýsigögn)'!$C$42:$C$58,0))="","",INDEX('Undirviðmiðalisti (Lýsigögn)'!F$42:F$58,MATCH($C8,'Undirviðmiðalisti (Lýsigögn)'!$C$42:$C$58,0))),"")))) | K8: =IF($C8="","",IF($G8="Einstaklingsbundið",IFERROR(IF(INDEX('Undirviðmiðalisti (Lýsigögn)'!G$42:G$58,MATCH($C8,'Undirviðmiðalisti (Lýsigögn)'!$C$42:$C$58,0))="","",INDEX('Undirviðmiðalisti (Lýsigögn)'!G$42:G$58,MATCH($C8,'Undirviðmiðalisti (Lýsigögn)'!$C$42:$C$58,0))),""),IFERROR(IF(INDEX('Undirviðmiðalisti (Lýsigögn)'!G$6:G$41,MATCH($C8,'Undirviðmiðalisti (Lýsigögn)'!$C$6:$C$41,0))="","",INDEX('Undirviðmiðalisti (Lýsigögn)'!G$6:G$41,MATCH($C8,'Undirviðmiðalisti (Lýsigögn)'!$C$6:$C$41,0))),IFERROR(IF(INDEX('Undirviðmiðalisti (Lýsigögn)'!G$42:G$58,MATCH($C8,'Undirviðmiðalisti (Lýsigögn)'!$C$42:$C$58,0))="","",INDEX('Undirviðmiðalisti (Lýsigögn)'!G$42:G$58,MATCH($C8,'Undirviðmiðalisti (Lýsigögn)'!$C$42:$C$58,0))),"")))) | L8: =IF($C8="","",IF($G8="Einstaklingsbundið",IFERROR(IF(INDEX('Undirviðmiðalisti (Lýsigögn)'!H$42:H$58,MATCH($C8,'Undirviðmiðalisti (Lýsigögn)'!$C$42:$C$58,0))="","",INDEX('Undirviðmiðalisti (Lýsigögn)'!H$42:H$58,MATCH($C8,'Undirviðmiðalisti (Lýsigögn)'!$C$42:$C$58,0))),""),IFERROR(IF(INDEX('Undirviðmiðalisti (Lýsigögn)'!H$6:H$41,MATCH($C8,'Undirviðmiðalisti (Lýsigögn)'!$C$6:$C$41,0))="","",INDEX('Undirviðmiðalisti (Lýsigögn)'!H$6:H$41,MATCH($C8,'Undirviðmiðalisti (Lýsigögn)'!$C$6:$C$41,0))),IFERROR(IF(INDEX('Undirviðmiðalisti (Lýsigögn)'!H$42:H$58,MATCH($C8,'Undirviðmiðalisti (Lýsigögn)'!$C$42:$C$58,0))="","",INDEX('Undirviðmiðalisti (Lýsigögn)'!H$42:H$58,MATCH($C8,'Undirviðmiðalisti (Lýsigögn)'!$C$42:$C$58,0))),"")))) | M8: =IF($C8="","",IF($G8="Einstaklingsbundið",IFERROR(IF(INDEX('Undirviðmiðalisti (Lýsigögn)'!I$42:I$58,MATCH($C8,'Undirviðmiðalisti (Lýsigögn)'!$C$42:$C$58,0))="","",INDEX('Undirviðmiðalisti (Lýsigögn)'!I$42:I$58,MATCH($C8,'Undirviðmiðalisti (Lýsigögn)'!$C$42:$C$58,0))),""),IFERROR(IF(INDEX('Undirviðmiðalisti (Lýsigögn)'!I$6:I$41,MATCH($C8,'Undirviðmiðalisti (Lýsigögn)'!$C$6:$C$41,0))="","",INDEX('Undirviðmiðalisti (Lýsigögn)'!I$6:I$41,MATCH($C8,'Undirviðmiðalisti (Lýsigögn)'!$C$6:$C$41,0))),IFERROR(IF(INDEX('Undirviðmiðalisti (Lýsigögn)'!I$42:I$58,MATCH($C8,'Undirviðmiðalisti (Lýsigögn)'!$C$42:$C$58,0))="","",INDEX('Undirviðmiðalisti (Lýsigögn)'!I$42:I$58,MATCH($C8,'Undirviðmiðalisti (Lýsigögn)'!$C$42:$C$58,0))),"")))) | N8: =IF($C8="","",IF($G8="Einstaklingsbundið",IFERROR(IF(INDEX('Undirviðmiðalisti (Lýsigögn)'!J$42:J$58,MATCH($C8,'Undirviðmiðalisti (Lýsigögn)'!$C$42:$C$58,0))="","",INDEX('Undirviðmiðalisti (Lýsigögn)'!J$42:J$58,MATCH($C8,'Undirviðmiðalisti (Lýsigögn)'!$C$42:$C$58,0))),""),IFERROR(IF(INDEX('Undirviðmiðalisti (Lýsigögn)'!J$6:J$41,MATCH($C8,'Undirviðmiðalisti (Lýsigögn)'!$C$6:$C$41,0))="","",INDEX('Undirviðmiðalisti (Lýsigögn)'!J$6:J$41,MATCH($C8,'Undirviðmiðalisti (Lýsigögn)'!$C$6:$C$41,0))),IFERROR(IF(INDEX('Undirviðmiðalisti (Lýsigögn)'!J$42:J$58,MATCH($C8,'Undirviðmiðalisti (Lýsigögn)'!$C$42:$C$58,0))="","",INDEX('Undirviðmiðalisti (Lýsigögn)'!J$42:J$58,MATCH($C8,'Undirviðmiðalisti (Lýsigögn)'!$C$42:$C$58,0))),"")))) | O8: =IF($C8="","",IF($G8="Einstaklingsbundið",IFERROR(IF(INDEX('Undirviðmiðalisti (Lýsigögn)'!K$42:K$58,MATCH($C8,'Undirviðmiðalisti (Lýsigögn)'!$C$42:$C$58,0))="","",INDEX('Undirviðmiðalisti (Lýsigögn)'!K$42:K$58,MATCH($C8,'Undirviðmiðalisti (Lýsigögn)'!$C$42:$C$58,0))),""),IFERROR(IF(INDEX('Undirviðmiðalisti (Lýsigögn)'!K$6:K$41,MATCH($C8,'Undirviðmiðalisti (Lýsigögn)'!$C$6:$C$41,0))="","",INDEX('Undirviðmiðalisti (Lýsigögn)'!K$6:K$41,MATCH($C8,'Undirviðmiðalisti (Lýsigögn)'!$C$6:$C$41,0))),IFERROR(IF(INDEX('Undirviðmiðalisti (Lýsigögn)'!K$42:K$58,MATCH($C8,'Undirviðmiðalisti (Lýsigögn)'!$C$42:$C$58,0))="","",INDEX('Undirviðmiðalisti (Lýsigögn)'!K$42:K$58,MATCH($C8,'Undirviðmiðalisti (Lýsigögn)'!$C$42:$C$58,0))),"")))) | P8: =IF($C8="","",IF($G8="Einstaklingsbundið",IFERROR(IF(INDEX('Undirviðmiðalisti (Lýsigögn)'!L$42:L$58,MATCH($C8,'Undirviðmiðalisti (Lýsigögn)'!$C$42:$C$58,0))="","",INDEX('Undirviðmiðalisti (Lýsigögn)'!L$42:L$58,MATCH($C8,'Undirviðmiðalisti (Lýsigögn)'!$C$42:$C$58,0))),""),IFERROR(IF(INDEX('Undirviðmiðalisti (Lýsigögn)'!L$6:L$41,MATCH($C8,'Undirviðmiðalisti (Lýsigögn)'!$C$6:$C$41,0))="","",INDEX('Undirviðmiðalisti (Lýsigögn)'!L$6:L$41,MATCH($C8,'Undirviðmiðalisti (Lýsigögn)'!$C$6:$C$41,0))),IFERROR(IF(INDEX('Undirviðmiðalisti (Lýsigögn)'!L$42:L$58,MATCH($C8,'Undirviðmiðalisti (Lýsigögn)'!$C$42:$C$58,0))="","",INDEX('Undirviðmiðalisti (Lýsigögn)'!L$42:L$58,MATCH($C8,'Undirviðmiðalisti (Lýsigögn)'!$C$42:$C$58,0))),"")))) | Q8: =IF($C8="","",IF($G8="Einstaklingsbundið",IFERROR(IF(INDEX('Undirviðmiðalisti (Lýsigögn)'!M$42:M$58,MATCH($C8,'Undirviðmiðalisti (Lýsigögn)'!$C$42:$C$58,0))="","",INDEX('Undirviðmiðalisti (Lýsigögn)'!M$42:M$58,MATCH($C8,'Undirviðmiðalisti (Lýsigögn)'!$C$42:$C$58,0))),""),IFERROR(IF(INDEX('Undirviðmiðalisti (Lýsigögn)'!M$6:M$41,MATCH($C8,'Undirviðmiðalisti (Lýsigögn)'!$C$6:$C$41,0))="","",INDEX('Undirviðmiðalisti (Lýsigögn)'!M$6:M$41,MATCH($C8,'Undirviðmiðalisti (Lýsigögn)'!$C$6:$C$41,0))),IFERROR(IF(INDEX('Undirviðmiðalisti (Lýsigögn)'!M$42:M$58,MATCH($C8,'Undirviðmiðalisti (Lýsigögn)'!$C$42:$C$58,0))="","",INDEX('Undirviðmiðalisti (Lýsigögn)'!M$42:M$58,MATCH($C8,'Undirviðmiðalisti (Lýsigögn)'!$C$42:$C$58,0))),""))))
A9: =IF($B9="","",ROW()-5) | D9: =IF($C9="","",IF($G9="Einstaklingsbundið",IFERROR(IF(INDEX('Undirviðmiðalisti (Lýsigögn)'!$D$42:$D$58,MATCH($C9,'Undirviðmiðalisti (Lýsigögn)'!$C$42:$C$58,0))="","",INDEX('Undirviðmiðalisti (Lýsigögn)'!$D$42:$D$58,MATCH($C9,'Undirviðmiðalisti (Lýsigögn)'!$C$42:$C$58,0))),""),IFERROR(IF(INDEX('Undirviðmiðalisti (Lýsigögn)'!$D$6:$D$41,MATCH($C9,'Undirviðmiðalisti (Lýsigögn)'!$C$6:$C$41,0))="","",INDEX('Undirviðmiðalisti (Lýsigögn)'!$D$6:$D$41,MATCH($C9,'Undirviðmiðalisti (Lýsigögn)'!$C$6:$C$41,0))),IFERROR(IF(INDEX('Undirviðmiðalisti (Lýsigögn)'!$D$42:$D$58,MATCH($C9,'Undirviðmiðalisti (Lýsigögn)'!$C$42:$C$58,0))="","",INDEX('Undirviðmiðalisti (Lýsigögn)'!$D$42:$D$58,MATCH($C9,'Undirviðmiðalisti (Lýsigögn)'!$C$42:$C$58,0))),"")))) | F9: =IF($C9="","",IF($G9="Einstaklingsbundið",IFERROR(IF(INDEX('Undirviðmiðalisti (Lýsigögn)'!$E$42:$E$58,MATCH($C9,'Undirviðmiðalisti (Lýsigögn)'!$C$42:$C$58,0))="","",INDEX('Undirviðmiðalisti (Lýsigögn)'!$E$42:$E$58,MATCH($C9,'Undirviðmiðalisti (Lýsigögn)'!$C$42:$C$58,0))),""),IFERROR(IF(INDEX('Undirviðmiðalisti (Lýsigögn)'!$E$6:$E$41,MATCH($C9,'Undirviðmiðalisti (Lýsigögn)'!$C$6:$C$41,0))="","",INDEX('Undirviðmiðalisti (Lýsigögn)'!$E$6:$E$41,MATCH($C9,'Undirviðmiðalisti (Lýsigögn)'!$C$6:$C$41,0))),IFERROR(IF(INDEX('Undirviðmiðalisti (Lýsigögn)'!$E$42:$E$58,MATCH($C9,'Undirviðmiðalisti (Lýsigögn)'!$C$42:$C$58,0))="","",INDEX('Undirviðmiðalisti (Lýsigögn)'!$E$42:$E$58,MATCH($C9,'Undirviðmiðalisti (Lýsigögn)'!$C$42:$C$58,0))),"")))) | G9: =IFERROR(IF(B9="","",INDEX(Viðmið!$B$6:$B$10,MATCH(B9,Viðmið!$C$6:$C$10,0))),"") | H9: =IF(OR(E9="",F9=""),"",E9*KVARDI) | I9: =IF(B9="","",IF(ROUND(SUMIF($B$6:$B$205,B9,$E$6:$E$205),4)=ROUND(IFERROR(INDEX(Viðmið!$E$6:$E$10,MATCH(B9,Viðmið!$C$6:$C$10,0)),-1),4),"✓","✗")) | J9: =IF($C9="","",IF($G9="Einstaklingsbundið",IFERROR(IF(INDEX('Undirviðmiðalisti (Lýsigögn)'!F$42:F$58,MATCH($C9,'Undirviðmiðalisti (Lýsigögn)'!$C$42:$C$58,0))="","",INDEX('Undirviðmiðalisti (Lýsigögn)'!F$42:F$58,MATCH($C9,'Undirviðmiðalisti (Lýsigögn)'!$C$42:$C$58,0))),""),IFERROR(IF(INDEX('Undirviðmiðalisti (Lýsigögn)'!F$6:F$41,MATCH($C9,'Undirviðmiðalisti (Lýsigögn)'!$C$6:$C$41,0))="","",INDEX('Undirviðmiðalisti (Lýsigögn)'!F$6:F$41,MATCH($C9,'Undirviðmiðalisti (Lýsigögn)'!$C$6:$C$41,0))),IFERROR(IF(INDEX('Undirviðmiðalisti (Lýsigögn)'!F$42:F$58,MATCH($C9,'Undirviðmiðalisti (Lýsigögn)'!$C$42:$C$58,0))="","",INDEX('Undirviðmiðalisti (Lýsigögn)'!F$42:F$58,MATCH($C9,'Undirviðmiðalisti (Lýsigögn)'!$C$42:$C$58,0))),"")))) | K9: =IF($C9="","",IF($G9="Einstaklingsbundið",IFERROR(IF(INDEX('Undirviðmiðalisti (Lýsigögn)'!G$42:G$58,MATCH($C9,'Undirviðmiðalisti (Lýsigögn)'!$C$42:$C$58,0))="","",INDEX('Undirviðmiðalisti (Lýsigögn)'!G$42:G$58,MATCH($C9,'Undirviðmiðalisti (Lýsigögn)'!$C$42:$C$58,0))),""),IFERROR(IF(INDEX('Undirviðmiðalisti (Lýsigögn)'!G$6:G$41,MATCH($C9,'Undirviðmiðalisti (Lýsigögn)'!$C$6:$C$41,0))="","",INDEX('Undirviðmiðalisti (Lýsigögn)'!G$6:G$41,MATCH($C9,'Undirviðmiðalisti (Lýsigögn)'!$C$6:$C$41,0))),IFERROR(IF(INDEX('Undirviðmiðalisti (Lýsigögn)'!G$42:G$58,MATCH($C9,'Undirviðmiðalisti (Lýsigögn)'!$C$42:$C$58,0))="","",INDEX('Undirviðmiðalisti (Lýsigögn)'!G$42:G$58,MATCH($C9,'Undirviðmiðalisti (Lýsigögn)'!$C$42:$C$58,0))),"")))) | L9: =IF($C9="","",IF($G9="Einstaklingsbundið",IFERROR(IF(INDEX('Undirviðmiðalisti (Lýsigögn)'!H$42:H$58,MATCH($C9,'Undirviðmiðalisti (Lýsigögn)'!$C$42:$C$58,0))="","",INDEX('Undirviðmiðalisti (Lýsigögn)'!H$42:H$58,MATCH($C9,'Undirviðmiðalisti (Lýsigögn)'!$C$42:$C$58,0))),""),IFERROR(IF(INDEX('Undirviðmiðalisti (Lýsigögn)'!H$6:H$41,MATCH($C9,'Undirviðmiðalisti (Lýsigögn)'!$C$6:$C$41,0))="","",INDEX('Undirviðmiðalisti (Lýsigögn)'!H$6:H$41,MATCH($C9,'Undirviðmiðalisti (Lýsigögn)'!$C$6:$C$41,0))),IFERROR(IF(INDEX('Undirviðmiðalisti (Lýsigögn)'!H$42:H$58,MATCH($C9,'Undirviðmiðalisti (Lýsigögn)'!$C$42:$C$58,0))="","",INDEX('Undirviðmiðalisti (Lýsigögn)'!H$42:H$58,MATCH($C9,'Undirviðmiðalisti (Lýsigögn)'!$C$42:$C$58,0))),"")))) | M9: =IF($C9="","",IF($G9="Einstaklingsbundið",IFERROR(IF(INDEX('Undirviðmiðalisti (Lýsigögn)'!I$42:I$58,MATCH($C9,'Undirviðmiðalisti (Lýsigögn)'!$C$42:$C$58,0))="","",INDEX('Undirviðmiðalisti (Lýsigögn)'!I$42:I$58,MATCH($C9,'Undirviðmiðalisti (Lýsigögn)'!$C$42:$C$58,0))),""),IFERROR(IF(INDEX('Undirviðmiðalisti (Lýsigögn)'!I$6:I$41,MATCH($C9,'Undirviðmiðalisti (Lýsigögn)'!$C$6:$C$41,0))="","",INDEX('Undirviðmiðalisti (Lýsigögn)'!I$6:I$41,MATCH($C9,'Undirviðmiðalisti (Lýsigögn)'!$C$6:$C$41,0))),IFERROR(IF(INDEX('Undirviðmiðalisti (Lýsigögn)'!I$42:I$58,MATCH($C9,'Undirviðmiðalisti (Lýsigögn)'!$C$42:$C$58,0))="","",INDEX('Undirviðmiðalisti (Lýsigögn)'!I$42:I$58,MATCH($C9,'Undirviðmiðalisti (Lýsigögn)'!$C$42:$C$58,0))),"")))) | N9: =IF($C9="","",IF($G9="Einstaklingsbundið",IFERROR(IF(INDEX('Undirviðmiðalisti (Lýsigögn)'!J$42:J$58,MATCH($C9,'Undirviðmiðalisti (Lýsigögn)'!$C$42:$C$58,0))="","",INDEX('Undirviðmiðalisti (Lýsigögn)'!J$42:J$58,MATCH($C9,'Undirviðmiðalisti (Lýsigögn)'!$C$42:$C$58,0))),""),IFERROR(IF(INDEX('Undirviðmiðalisti (Lýsigögn)'!J$6:J$41,MATCH($C9,'Undirviðmiðalisti (Lýsigögn)'!$C$6:$C$41,0))="","",INDEX('Undirviðmiðalisti (Lýsigögn)'!J$6:J$41,MATCH($C9,'Undirviðmiðalisti (Lýsigögn)'!$C$6:$C$41,0))),IFERROR(IF(INDEX('Undirviðmiðalisti (Lýsigögn)'!J$42:J$58,MATCH($C9,'Undirviðmiðalisti (Lýsigögn)'!$C$42:$C$58,0))="","",INDEX('Undirviðmiðalisti (Lýsigögn)'!J$42:J$58,MATCH($C9,'Undirviðmiðalisti (Lýsigögn)'!$C$42:$C$58,0))),"")))) | O9: =IF($C9="","",IF($G9="Einstaklingsbundið",IFERROR(IF(INDEX('Undirviðmiðalisti (Lýsigögn)'!K$42:K$58,MATCH($C9,'Undirviðmiðalisti (Lýsigögn)'!$C$42:$C$58,0))="","",INDEX('Undirviðmiðalisti (Lýsigögn)'!K$42:K$58,MATCH($C9,'Undirviðmiðalisti (Lýsigögn)'!$C$42:$C$58,0))),""),IFERROR(IF(INDEX('Undirviðmiðalisti (Lýsigögn)'!K$6:K$41,MATCH($C9,'Undirviðmiðalisti (Lýsigögn)'!$C$6:$C$41,0))="","",INDEX('Undirviðmiðalisti (Lýsigögn)'!K$6:K$41,MATCH($C9,'Undirviðmiðalisti (Lýsigögn)'!$C$6:$C$41,0))),IFERROR(IF(INDEX('Undirviðmiðalisti (Lýsigögn)'!K$42:K$58,MATCH($C9,'Undirviðmiðalisti (Lýsigögn)'!$C$42:$C$58,0))="","",INDEX('Undirviðmiðalisti (Lýsigögn)'!K$42:K$58,MATCH($C9,'Undirviðmiðalisti (Lýsigögn)'!$C$42:$C$58,0))),"")))) | P9: =IF($C9="","",IF($G9="Einstaklingsbundið",IFERROR(IF(INDEX('Undirviðmiðalisti (Lýsigögn)'!L$42:L$58,MATCH($C9,'Undirviðmiðalisti (Lýsigögn)'!$C$42:$C$58,0))="","",INDEX('Undirviðmiðalisti (Lýsigögn)'!L$42:L$58,MATCH($C9,'Undirviðmiðalisti (Lýsigögn)'!$C$42:$C$58,0))),""),IFERROR(IF(INDEX('Undirviðmiðalisti (Lýsigögn)'!L$6:L$41,MATCH($C9,'Undirviðmiðalisti (Lýsigögn)'!$C$6:$C$41,0))="","",INDEX('Undirviðmiðalisti (Lýsigögn)'!L$6:L$41,MATCH($C9,'Undirviðmiðalisti (Lýsigögn)'!$C$6:$C$41,0))),IFERROR(IF(INDEX('Undirviðmiðalisti (Lýsigögn)'!L$42:L$58,MATCH($C9,'Undirviðmiðalisti (Lýsigögn)'!$C$42:$C$58,0))="","",INDEX('Undirviðmiðalisti (Lýsigögn)'!L$42:L$58,MATCH($C9,'Undirviðmiðalisti (Lýsigögn)'!$C$42:$C$58,0))),"")))) | Q9: =IF($C9="","",IF($G9="Einstaklingsbundið",IFERROR(IF(INDEX('Undirviðmiðalisti (Lýsigögn)'!M$42:M$58,MATCH($C9,'Undirviðmiðalisti (Lýsigögn)'!$C$42:$C$58,0))="","",INDEX('Undirviðmiðalisti (Lýsigögn)'!M$42:M$58,MATCH($C9,'Undirviðmiðalisti (Lýsigögn)'!$C$42:$C$58,0))),""),IFERROR(IF(INDEX('Undirviðmiðalisti (Lýsigögn)'!M$6:M$41,MATCH($C9,'Undirviðmiðalisti (Lýsigögn)'!$C$6:$C$41,0))="","",INDEX('Undirviðmiðalisti (Lýsigögn)'!M$6:M$41,MATCH($C9,'Undirviðmiðalisti (Lýsigögn)'!$C$6:$C$41,0))),IFERROR(IF(INDEX('Undirviðmiðalisti (Lýsigögn)'!M$42:M$58,MATCH($C9,'Undirviðmiðalisti (Lýsigögn)'!$C$42:$C$58,0))="","",INDEX('Undirviðmiðalisti (Lýsigögn)'!M$42:M$58,MATCH($C9,'Undirviðmiðalisti (Lýsigögn)'!$C$42:$C$58,0))),""))))
A10: =IF($B10="","",ROW()-5) | D10: =IF($C10="","",IF($G10="Einstaklingsbundið",IFERROR(IF(INDEX('Undirviðmiðalisti (Lýsigögn)'!$D$42:$D$58,MATCH($C10,'Undirviðmiðalisti (Lýsigögn)'!$C$42:$C$58,0))="","",INDEX('Undirviðmiðalisti (Lýsigögn)'!$D$42:$D$58,MATCH($C10,'Undirviðmiðalisti (Lýsigögn)'!$C$42:$C$58,0))),""),IFERROR(IF(INDEX('Undirviðmiðalisti (Lýsigögn)'!$D$6:$D$41,MATCH($C10,'Undirviðmiðalisti (Lýsigögn)'!$C$6:$C$41,0))="","",INDEX('Undirviðmiðalisti (Lýsigögn)'!$D$6:$D$41,MATCH($C10,'Undirviðmiðalisti (Lýsigögn)'!$C$6:$C$41,0))),IFERROR(IF(INDEX('Undirviðmiðalisti (Lýsigögn)'!$D$42:$D$58,MATCH($C10,'Undirviðmiðalisti (Lýsigögn)'!$C$42:$C$58,0))="","",INDEX('Undirviðmiðalisti (Lýsigögn)'!$D$42:$D$58,MATCH($C10,'Undirviðmiðalisti (Lýsigögn)'!$C$42:$C$58,0))),"")))) | F10: =IF($C10="","",IF($G10="Einstaklingsbundið",IFERROR(IF(INDEX('Undirviðmiðalisti (Lýsigögn)'!$E$42:$E$58,MATCH($C10,'Undirviðmiðalisti (Lýsigögn)'!$C$42:$C$58,0))="","",INDEX('Undirviðmiðalisti (Lýsigögn)'!$E$42:$E$58,MATCH($C10,'Undirviðmiðalisti (Lýsigögn)'!$C$42:$C$58,0))),""),IFERROR(IF(INDEX('Undirviðmiðalisti (Lýsigögn)'!$E$6:$E$41,MATCH($C10,'Undirviðmiðalisti (Lýsigögn)'!$C$6:$C$41,0))="","",INDEX('Undirviðmiðalisti (Lýsigögn)'!$E$6:$E$41,MATCH($C10,'Undirviðmiðalisti (Lýsigögn)'!$C$6:$C$41,0))),IFERROR(IF(INDEX('Undirviðmiðalisti (Lýsigögn)'!$E$42:$E$58,MATCH($C10,'Undirviðmiðalisti (Lýsigögn)'!$C$42:$C$58,0))="","",INDEX('Undirviðmiðalisti (Lýsigögn)'!$E$42:$E$58,MATCH($C10,'Undirviðmiðalisti (Lýsigögn)'!$C$42:$C$58,0))),"")))) | G10: =IFERROR(IF(B10="","",INDEX(Viðmið!$B$6:$B$10,MATCH(B10,Viðmið!$C$6:$C$10,0))),"") | H10: =IF(OR(E10="",F10=""),"",E10*KVARDI) | I10: =IF(B10="","",IF(ROUND(SUMIF($B$6:$B$205,B10,$E$6:$E$205),4)=ROUND(IFERROR(INDEX(Viðmið!$E$6:$E$10,MATCH(B10,Viðmið!$C$6:$C$10,0)),-1),4),"✓","✗")) | J10: =IF($C10="","",IF($G10="Einstaklingsbundið",IFERROR(IF(INDEX('Undirviðmiðalisti (Lýsigögn)'!F$42:F$58,MATCH($C10,'Undirviðmiðalisti (Lýsigögn)'!$C$42:$C$58,0))="","",INDEX('Undirviðmiðalisti (Lýsigögn)'!F$42:F$58,MATCH($C10,'Undirviðmiðalisti (Lýsigögn)'!$C$42:$C$58,0))),""),IFERROR(IF(INDEX('Undirviðmiðalisti (Lýsigögn)'!F$6:F$41,MATCH($C10,'Undirviðmiðalisti (Lýsigögn)'!$C$6:$C$41,0))="","",INDEX('Undirviðmiðalisti (Lýsigögn)'!F$6:F$41,MATCH($C10,'Undirviðmiðalisti (Lýsigögn)'!$C$6:$C$41,0))),IFERROR(IF(INDEX('Undirviðmiðalisti (Lýsigögn)'!F$42:F$58,MATCH($C10,'Undirviðmiðalisti (Lýsigögn)'!$C$42:$C$58,0))="","",INDEX('Undirviðmiðalisti (Lýsigögn)'!F$42:F$58,MATCH($C10,'Undirviðmiðalisti (Lýsigögn)'!$C$42:$C$58,0))),"")))) | K10: =IF($C10="","",IF($G10="Einstaklingsbundið",IFERROR(IF(INDEX('Undirviðmiðalisti (Lýsigögn)'!G$42:G$58,MATCH($C10,'Undirviðmiðalisti (Lýsigögn)'!$C$42:$C$58,0))="","",INDEX('Undirviðmiðalisti (Lýsigögn)'!G$42:G$58,MATCH($C10,'Undirviðmiðalisti (Lýsigögn)'!$C$42:$C$58,0))),""),IFERROR(IF(INDEX('Undirviðmiðalisti (Lýsigögn)'!G$6:G$41,MATCH($C10,'Undirviðmiðalisti (Lýsigögn)'!$C$6:$C$41,0))="","",INDEX('Undirviðmiðalisti (Lýsigögn)'!G$6:G$41,MATCH($C10,'Undirviðmiðalisti (Lýsigögn)'!$C$6:$C$41,0))),IFERROR(IF(INDEX('Undirviðmiðalisti (Lýsigögn)'!G$42:G$58,MATCH($C10,'Undirviðmiðalisti (Lýsigögn)'!$C$42:$C$58,0))="","",INDEX('Undirviðmiðalisti (Lýsigögn)'!G$42:G$58,MATCH($C10,'Undirviðmiðalisti (Lýsigögn)'!$C$42:$C$58,0))),"")))) | L10: =IF($C10="","",IF($G10="Einstaklingsbundið",IFERROR(IF(INDEX('Undirviðmiðalisti (Lýsigögn)'!H$42:H$58,MATCH($C10,'Undirviðmiðalisti (Lýsigögn)'!$C$42:$C$58,0))="","",INDEX('Undirviðmiðalisti (Lýsigögn)'!H$42:H$58,MATCH($C10,'Undirviðmiðalisti (Lýsigögn)'!$C$42:$C$58,0))),""),IFERROR(IF(INDEX('Undirviðmiðalisti (Lýsigögn)'!H$6:H$41,MATCH($C10,'Undirviðmiðalisti (Lýsigögn)'!$C$6:$C$41,0))="","",INDEX('Undirviðmiðalisti (Lýsigögn)'!H$6:H$41,MATCH($C10,'Undirviðmiðalisti (Lýsigögn)'!$C$6:$C$41,0))),IFERROR(IF(INDEX('Undirviðmiðalisti (Lýsigögn)'!H$42:H$58,MATCH($C10,'Undirviðmiðalisti (Lýsigögn)'!$C$42:$C$58,0))="","",INDEX('Undirviðmiðalisti (Lýsigögn)'!H$42:H$58,MATCH($C10,'Undirviðmiðalisti (Lýsigögn)'!$C$42:$C$58,0))),"")))) | M10: =IF($C10="","",IF($G10="Einstaklingsbundið",IFERROR(IF(INDEX('Undirviðmiðalisti (Lýsigögn)'!I$42:I$58,MATCH($C10,'Undirviðmiðalisti (Lýsigögn)'!$C$42:$C$58,0))="","",INDEX('Undirviðmiðalisti (Lýsigögn)'!I$42:I$58,MATCH($C10,'Undirviðmiðalisti (Lýsigögn)'!$C$42:$C$58,0))),""),IFERROR(IF(INDEX('Undirviðmiðalisti (Lýsigögn)'!I$6:I$41,MATCH($C10,'Undirviðmiðalisti (Lýsigögn)'!$C$6:$C$41,0))="","",INDEX('Undirviðmiðalisti (Lýsigögn)'!I$6:I$41,MATCH($C10,'Undirviðmiðalisti (Lýsigögn)'!$C$6:$C$41,0))),IFERROR(IF(INDEX('Undirviðmiðalisti (Lýsigögn)'!I$42:I$58,MATCH($C10,'Undirviðmiðalisti (Lýsigögn)'!$C$42:$C$58,0))="","",INDEX('Undirviðmiðalisti (Lýsigögn)'!I$42:I$58,MATCH($C10,'Undirviðmiðalisti (Lýsigögn)'!$C$42:$C$58,0))),"")))) | N10: =IF($C10="","",IF($G10="Einstaklingsbundið",IFERROR(IF(INDEX('Undirviðmiðalisti (Lýsigögn)'!J$42:J$58,MATCH($C10,'Undirviðmiðalisti (Lýsigögn)'!$C$42:$C$58,0))="","",INDEX('Undirviðmiðalisti (Lýsigögn)'!J$42:J$58,MATCH($C10,'Undirviðmiðalisti (Lýsigögn)'!$C$42:$C$58,0))),""),IFERROR(IF(INDEX('Undirviðmiðalisti (Lýsigögn)'!J$6:J$41,MATCH($C10,'Undirviðmiðalisti (Lýsigögn)'!$C$6:$C$41,0))="","",INDEX('Undirviðmiðalisti (Lýsigögn)'!J$6:J$41,MATCH($C10,'Undirviðmiðalisti (Lýsigögn)'!$C$6:$C$41,0))),IFERROR(IF(INDEX('Undirviðmiðalisti (Lýsigögn)'!J$42:J$58,MATCH($C10,'Undirviðmiðalisti (Lýsigögn)'!$C$42:$C$58,0))="","",INDEX('Undirviðmiðalisti (Lýsigögn)'!J$42:J$58,MATCH($C10,'Undirviðmiðalisti (Lýsigögn)'!$C$42:$C$58,0))),"")))) | O10: =IF($C10="","",IF($G10="Einstaklingsbundið",IFERROR(IF(INDEX('Undirviðmiðalisti (Lýsigögn)'!K$42:K$58,MATCH($C10,'Undirviðmiðalisti (Lýsigögn)'!$C$42:$C$58,0))="","",INDEX('Undirviðmiðalisti (Lýsigögn)'!K$42:K$58,MATCH($C10,'Undirviðmiðalisti (Lýsigögn)'!$C$42:$C$58,0))),""),IFERROR(IF(INDEX('Undirviðmiðalisti (Lýsigögn)'!K$6:K$41,MATCH($C10,'Undirviðmiðalisti (Lýsigögn)'!$C$6:$C$41,0))="","",INDEX('Undirviðmiðalisti (Lýsigögn)'!K$6:K$41,MATCH($C10,'Undirviðmiðalisti (Lýsigögn)'!$C$6:$C$41,0))),IFERROR(IF(INDEX('Undirviðmiðalisti (Lýsigögn)'!K$42:K$58,MATCH($C10,'Undirviðmiðalisti (Lýsigögn)'!$C$42:$C$58,0))="","",INDEX('Undirviðmiðalisti (Lýsigögn)'!K$42:K$58,MATCH($C10,'Undirviðmiðalisti (Lýsigögn)'!$C$42:$C$58,0))),"")))) | P10: =IF($C10="","",IF($G10="Einstaklingsbundið",IFERROR(IF(INDEX('Undirviðmiðalisti (Lýsigögn)'!L$42:L$58,MATCH($C10,'Undirviðmiðalisti (Lýsigögn)'!$C$42:$C$58,0))="","",INDEX('Undirviðmiðalisti (Lýsigögn)'!L$42:L$58,MATCH($C10,'Undirviðmiðalisti (Lýsigögn)'!$C$42:$C$58,0))),""),IFERROR(IF(INDEX('Undirviðmiðalisti (Lýsigögn)'!L$6:L$41,MATCH($C10,'Undirviðmiðalisti (Lýsigögn)'!$C$6:$C$41,0))="","",INDEX('Undirviðmiðalisti (Lýsigögn)'!L$6:L$41,MATCH($C10,'Undirviðmiðalisti (Lýsigögn)'!$C$6:$C$41,0))),IFERROR(IF(INDEX('Undirviðmiðalisti (Lýsigögn)'!L$42:L$58,MATCH($C10,'Undirviðmiðalisti (Lýsigögn)'!$C$42:$C$58,0))="","",INDEX('Undirviðmiðalisti (Lýsigögn)'!L$42:L$58,MATCH($C10,'Undirviðmiðalisti (Lýsigögn)'!$C$42:$C$58,0))),"")))) | Q10: =IF($C10="","",IF($G10="Einstaklingsbundið",IFERROR(IF(INDEX('Undirviðmiðalisti (Lýsigögn)'!M$42:M$58,MATCH($C10,'Undirviðmiðalisti (Lýsigögn)'!$C$42:$C$58,0))="","",INDEX('Undirviðmiðalisti (Lýsigögn)'!M$42:M$58,MATCH($C10,'Undirviðmiðalisti (Lýsigögn)'!$C$42:$C$58,0))),""),IFERROR(IF(INDEX('Undirviðmiðalisti (Lýsigögn)'!M$6:M$41,MATCH($C10,'Undirviðmiðalisti (Lýsigögn)'!$C$6:$C$41,0))="","",INDEX('Undirviðmiðalisti (Lýsigögn)'!M$6:M$41,MATCH($C10,'Undirviðmiðalisti (Lýsigögn)'!$C$6:$C$41,0))),IFERROR(IF(INDEX('Undirviðmiðalisti (Lýsigögn)'!M$42:M$58,MATCH($C10,'Undirviðmiðalisti (Lýsigögn)'!$C$42:$C$58,0))="","",INDEX('Undirviðmiðalisti (Lýsigögn)'!M$42:M$58,MATCH($C10,'Undirviðmiðalisti (Lýsigögn)'!$C$42:$C$58,0))),""))))
A11: =IF($B11="","",ROW()-5) | D11: =IF($C11="","",IF($G11="Einstaklingsbundið",IFERROR(IF(INDEX('Undirviðmiðalisti (Lýsigögn)'!$D$42:$D$58,MATCH($C11,'Undirviðmiðalisti (Lýsigögn)'!$C$42:$C$58,0))="","",INDEX('Undirviðmiðalisti (Lýsigögn)'!$D$42:$D$58,MATCH($C11,'Undirviðmiðalisti (Lýsigögn)'!$C$42:$C$58,0))),""),IFERROR(IF(INDEX('Undirviðmiðalisti (Lýsigögn)'!$D$6:$D$41,MATCH($C11,'Undirviðmiðalisti (Lýsigögn)'!$C$6:$C$41,0))="","",INDEX('Undirviðmiðalisti (Lýsigögn)'!$D$6:$D$41,MATCH($C11,'Undirviðmiðalisti (Lýsigögn)'!$C$6:$C$41,0))),IFERROR(IF(INDEX('Undirviðmiðalisti (Lýsigögn)'!$D$42:$D$58,MATCH($C11,'Undirviðmiðalisti (Lýsigögn)'!$C$42:$C$58,0))="","",INDEX('Undirviðmiðalisti (Lýsigögn)'!$D$42:$D$58,MATCH($C11,'Undirviðmiðalisti (Lýsigögn)'!$C$42:$C$58,0))),"")))) | F11: =IF($C11="","",IF($G11="Einstaklingsbundið",IFERROR(IF(INDEX('Undirviðmiðalisti (Lýsigögn)'!$E$42:$E$58,MATCH($C11,'Undirviðmiðalisti (Lýsigögn)'!$C$42:$C$58,0))="","",INDEX('Undirviðmiðalisti (Lýsigögn)'!$E$42:$E$58,MATCH($C11,'Undirviðmiðalisti (Lýsigögn)'!$C$42:$C$58,0))),""),IFERROR(IF(INDEX('Undirviðmiðalisti (Lýsigögn)'!$E$6:$E$41,MATCH($C11,'Undirviðmiðalisti (Lýsigögn)'!$C$6:$C$41,0))="","",INDEX('Undirviðmiðalisti (Lýsigögn)'!$E$6:$E$41,MATCH($C11,'Undirviðmiðalisti (Lýsigögn)'!$C$6:$C$41,0))),IFERROR(IF(INDEX('Undirviðmiðalisti (Lýsigögn)'!$E$42:$E$58,MATCH($C11,'Undirviðmiðalisti (Lýsigögn)'!$C$42:$C$58,0))="","",INDEX('Undirviðmiðalisti (Lýsigögn)'!$E$42:$E$58,MATCH($C11,'Undirviðmiðalisti (Lýsigögn)'!$C$42:$C$58,0))),"")))) | G11: =IFERROR(IF(B11="","",INDEX(Viðmið!$B$6:$B$10,MATCH(B11,Viðmið!$C$6:$C$10,0))),"") | H11: =IF(OR(E11="",F11=""),"",E11*KVARDI) | I11: =IF(B11="","",IF(ROUND(SUMIF($B$6:$B$205,B11,$E$6:$E$205),4)=ROUND(IFERROR(INDEX(Viðmið!$E$6:$E$10,MATCH(B11,Viðmið!$C$6:$C$10,0)),-1),4),"✓","✗")) | J11: =IF($C11="","",IF($G11="Einstaklingsbundið",IFERROR(IF(INDEX('Undirviðmiðalisti (Lýsigögn)'!F$42:F$58,MATCH($C11,'Undirviðmiðalisti (Lýsigögn)'!$C$42:$C$58,0))="","",INDEX('Undirviðmiðalisti (Lýsigögn)'!F$42:F$58,MATCH($C11,'Undirviðmiðalisti (Lýsigögn)'!$C$42:$C$58,0))),""),IFERROR(IF(INDEX('Undirviðmiðalisti (Lýsigögn)'!F$6:F$41,MATCH($C11,'Undirviðmiðalisti (Lýsigögn)'!$C$6:$C$41,0))="","",INDEX('Undirviðmiðalisti (Lýsigögn)'!F$6:F$41,MATCH($C11,'Undirviðmiðalisti (Lýsigögn)'!$C$6:$C$41,0))),IFERROR(IF(INDEX('Undirviðmiðalisti (Lýsigögn)'!F$42:F$58,MATCH($C11,'Undirviðmiðalisti (Lýsigögn)'!$C$42:$C$58,0))="","",INDEX('Undirviðmiðalisti (Lýsigögn)'!F$42:F$58,MATCH($C11,'Undirviðmiðalisti (Lýsigögn)'!$C$42:$C$58,0))),"")))) | K11: =IF($C11="","",IF($G11="Einstaklingsbundið",IFERROR(IF(INDEX('Undirviðmiðalisti (Lýsigögn)'!G$42:G$58,MATCH($C11,'Undirviðmiðalisti (Lýsigögn)'!$C$42:$C$58,0))="","",INDEX('Undirviðmiðalisti (Lýsigögn)'!G$42:G$58,MATCH($C11,'Undirviðmiðalisti (Lýsigögn)'!$C$42:$C$58,0))),""),IFERROR(IF(INDEX('Undirviðmiðalisti (Lýsigögn)'!G$6:G$41,MATCH($C11,'Undirviðmiðalisti (Lýsigögn)'!$C$6:$C$41,0))="","",INDEX('Undirviðmiðalisti (Lýsigögn)'!G$6:G$41,MATCH($C11,'Undirviðmiðalisti (Lýsigögn)'!$C$6:$C$41,0))),IFERROR(IF(INDEX('Undirviðmiðalisti (Lýsigögn)'!G$42:G$58,MATCH($C11,'Undirviðmiðalisti (Lýsigögn)'!$C$42:$C$58,0))="","",INDEX('Undirviðmiðalisti (Lýsigögn)'!G$42:G$58,MATCH($C11,'Undirviðmiðalisti (Lýsigögn)'!$C$42:$C$58,0))),"")))) | L11: =IF($C11="","",IF($G11="Einstaklingsbundið",IFERROR(IF(INDEX('Undirviðmiðalisti (Lýsigögn)'!H$42:H$58,MATCH($C11,'Undirviðmiðalisti (Lýsigögn)'!$C$42:$C$58,0))="","",INDEX('Undirviðmiðalisti (Lýsigögn)'!H$42:H$58,MATCH($C11,'Undirviðmiðalisti (Lýsigögn)'!$C$42:$C$58,0))),""),IFERROR(IF(INDEX('Undirviðmiðalisti (Lýsigögn)'!H$6:H$41,MATCH($C11,'Undirviðmiðalisti (Lýsigögn)'!$C$6:$C$41,0))="","",INDEX('Undirviðmiðalisti (Lýsigögn)'!H$6:H$41,MATCH($C11,'Undirviðmiðalisti (Lýsigögn)'!$C$6:$C$41,0))),IFERROR(IF(INDEX('Undirviðmiðalisti (Lýsigögn)'!H$42:H$58,MATCH($C11,'Undirviðmiðalisti (Lýsigögn)'!$C$42:$C$58,0))="","",INDEX('Undirviðmiðalisti (Lýsigögn)'!H$42:H$58,MATCH($C11,'Undirviðmiðalisti (Lýsigögn)'!$C$42:$C$58,0))),"")))) | M11: =IF($C11="","",IF($G11="Einstaklingsbundið",IFERROR(IF(INDEX('Undirviðmiðalisti (Lýsigögn)'!I$42:I$58,MATCH($C11,'Undirviðmiðalisti (Lýsigögn)'!$C$42:$C$58,0))="","",INDEX('Undirviðmiðalisti (Lýsigögn)'!I$42:I$58,MATCH($C11,'Undirviðmiðalisti (Lýsigögn)'!$C$42:$C$58,0))),""),IFERROR(IF(INDEX('Undirviðmiðalisti (Lýsigögn)'!I$6:I$41,MATCH($C11,'Undirviðmiðalisti (Lýsigögn)'!$C$6:$C$41,0))="","",INDEX('Undirviðmiðalisti (Lýsigögn)'!I$6:I$41,MATCH($C11,'Undirviðmiðalisti (Lýsigögn)'!$C$6:$C$41,0))),IFERROR(IF(INDEX('Undirviðmiðalisti (Lýsigögn)'!I$42:I$58,MATCH($C11,'Undirviðmiðalisti (Lýsigögn)'!$C$42:$C$58,0))="","",INDEX('Undirviðmiðalisti (Lýsigögn)'!I$42:I$58,MATCH($C11,'Undirviðmiðalisti (Lýsigögn)'!$C$42:$C$58,0))),"")))) | N11: =IF($C11="","",IF($G11="Einstaklingsbundið",IFERROR(IF(INDEX('Undirviðmiðalisti (Lýsigögn)'!J$42:J$58,MATCH($C11,'Undirviðmiðalisti (Lýsigögn)'!$C$42:$C$58,0))="","",INDEX('Undirviðmiðalisti (Lýsigögn)'!J$42:J$58,MATCH($C11,'Undirviðmiðalisti (Lýsigögn)'!$C$42:$C$58,0))),""),IFERROR(IF(INDEX('Undirviðmiðalisti (Lýsigögn)'!J$6:J$41,MATCH($C11,'Undirviðmiðalisti (Lýsigögn)'!$C$6:$C$41,0))="","",INDEX('Undirviðmiðalisti (Lýsigögn)'!J$6:J$41,MATCH($C11,'Undirviðmiðalisti (Lýsigögn)'!$C$6:$C$41,0))),IFERROR(IF(INDEX('Undirviðmiðalisti (Lýsigögn)'!J$42:J$58,MATCH($C11,'Undirviðmiðalisti (Lýsigögn)'!$C$42:$C$58,0))="","",INDEX('Undirviðmiðalisti (Lýsigögn)'!J$42:J$58,MATCH($C11,'Undirviðmiðalisti (Lýsigögn)'!$C$42:$C$58,0))),"")))) | O11: =IF($C11="","",IF($G11="Einstaklingsbundið",IFERROR(IF(INDEX('Undirviðmiðalisti (Lýsigögn)'!K$42:K$58,MATCH($C11,'Undirviðmiðalisti (Lýsigögn)'!$C$42:$C$58,0))="","",INDEX('Undirviðmiðalisti (Lýsigögn)'!K$42:K$58,MATCH($C11,'Undirviðmiðalisti (Lýsigögn)'!$C$42:$C$58,0))),""),IFERROR(IF(INDEX('Undirviðmiðalisti (Lýsigögn)'!K$6:K$41,MATCH($C11,'Undirviðmiðalisti (Lýsigögn)'!$C$6:$C$41,0))="","",INDEX('Undirviðmiðalisti (Lýsigögn)'!K$6:K$41,MATCH($C11,'Undirviðmiðalisti (Lýsigögn)'!$C$6:$C$41,0))),IFERROR(IF(INDEX('Undirviðmiðalisti (Lýsigögn)'!K$42:K$58,MATCH($C11,'Undirviðmiðalisti (Lýsigögn)'!$C$42:$C$58,0))="","",INDEX('Undirviðmiðalisti (Lýsigögn)'!K$42:K$58,MATCH($C11,'Undirviðmiðalisti (Lýsigögn)'!$C$42:$C$58,0))),"")))) | P11: =IF($C11="","",IF($G11="Einstaklingsbundið",IFERROR(IF(INDEX('Undirviðmiðalisti (Lýsigögn)'!L$42:L$58,MATCH($C11,'Undirviðmiðalisti (Lýsigögn)'!$C$42:$C$58,0))="","",INDEX('Undirviðmiðalisti (Lýsigögn)'!L$42:L$58,MATCH($C11,'Undirviðmiðalisti (Lýsigögn)'!$C$42:$C$58,0))),""),IFERROR(IF(INDEX('Undirviðmiðalisti (Lýsigögn)'!L$6:L$41,MATCH($C11,'Undirviðmiðalisti (Lýsigögn)'!$C$6:$C$41,0))="","",INDEX('Undirviðmiðalisti (Lýsigögn)'!L$6:L$41,MATCH($C11,'Undirviðmiðalisti (Lýsigögn)'!$C$6:$C$41,0))),IFERROR(IF(INDEX('Undirviðmiðalisti (Lýsigögn)'!L$42:L$58,MATCH($C11,'Undirviðmiðalisti (Lýsigögn)'!$C$42:$C$58,0))="","",INDEX('Undirviðmiðalisti (Lýsigögn)'!L$42:L$58,MATCH($C11,'Undirviðmiðalisti (Lýsigögn)'!$C$42:$C$58,0))),"")))) | Q11: =IF($C11="","",IF($G11="Einstaklingsbundið",IFERROR(IF(INDEX('Undirviðmiðalisti (Lýsigögn)'!M$42:M$58,MATCH($C11,'Undirviðmiðalisti (Lýsigögn)'!$C$42:$C$58,0))="","",INDEX('Undirviðmiðalisti (Lýsigögn)'!M$42:M$58,MATCH($C11,'Undirviðmiðalisti (Lýsigögn)'!$C$42:$C$58,0))),""),IFERROR(IF(INDEX('Undirviðmiðalisti (Lýsigögn)'!M$6:M$41,MATCH($C11,'Undirviðmiðalisti (Lýsigögn)'!$C$6:$C$41,0))="","",INDEX('Undirviðmiðalisti (Lýsigögn)'!M$6:M$41,MATCH($C11,'Undirviðmiðalisti (Lýsigögn)'!$C$6:$C$41,0))),IFERROR(IF(INDEX('Undirviðmiðalisti (Lýsigögn)'!M$42:M$58,MATCH($C11,'Undirviðmiðalisti (Lýsigögn)'!$C$42:$C$58,0))="","",INDEX('Undirviðmiðalisti (Lýsigögn)'!M$42:M$58,MATCH($C11,'Undirviðmiðalisti (Lýsigögn)'!$C$42:$C$58,0))),""))))
A12: =IF($B12="","",ROW()-5) | D12: =IF($C12="","",IF($G12="Einstaklingsbundið",IFERROR(IF(INDEX('Undirviðmiðalisti (Lýsigögn)'!$D$42:$D$58,MATCH($C12,'Undirviðmiðalisti (Lýsigögn)'!$C$42:$C$58,0))="","",INDEX('Undirviðmiðalisti (Lýsigögn)'!$D$42:$D$58,MATCH($C12,'Undirviðmiðalisti (Lýsigögn)'!$C$42:$C$58,0))),""),IFERROR(IF(INDEX('Undirviðmiðalisti (Lýsigögn)'!$D$6:$D$41,MATCH($C12,'Undirviðmiðalisti (Lýsigögn)'!$C$6:$C$41,0))="","",INDEX('Undirviðmiðalisti (Lýsigögn)'!$D$6:$D$41,MATCH($C12,'Undirviðmiðalisti (Lýsigögn)'!$C$6:$C$41,0))),IFERROR(IF(INDEX('Undirviðmiðalisti (Lýsigögn)'!$D$42:$D$58,MATCH($C12,'Undirviðmiðalisti (Lýsigögn)'!$C$42:$C$58,0))="","",INDEX('Undirviðmiðalisti (Lýsigögn)'!$D$42:$D$58,MATCH($C12,'Undirviðmiðalisti (Lýsigögn)'!$C$42:$C$58,0))),"")))) | F12: =IF($C12="","",IF($G12="Einstaklingsbundið",IFERROR(IF(INDEX('Undirviðmiðalisti (Lýsigögn)'!$E$42:$E$58,MATCH($C12,'Undirviðmiðalisti (Lýsigögn)'!$C$42:$C$58,0))="","",INDEX('Undirviðmiðalisti (Lýsigögn)'!$E$42:$E$58,MATCH($C12,'Undirviðmiðalisti (Lýsigögn)'!$C$42:$C$58,0))),""),IFERROR(IF(INDEX('Undirviðmiðalisti (Lýsigögn)'!$E$6:$E$41,MATCH($C12,'Undirviðmiðalisti (Lýsigögn)'!$C$6:$C$41,0))="","",INDEX('Undirviðmiðalisti (Lýsigögn)'!$E$6:$E$41,MATCH($C12,'Undirviðmiðalisti (Lýsigögn)'!$C$6:$C$41,0))),IFERROR(IF(INDEX('Undirviðmiðalisti (Lýsigögn)'!$E$42:$E$58,MATCH($C12,'Undirviðmiðalisti (Lýsigögn)'!$C$42:$C$58,0))="","",INDEX('Undirviðmiðalisti (Lýsigögn)'!$E$42:$E$58,MATCH($C12,'Undirviðmiðalisti (Lýsigögn)'!$C$42:$C$58,0))),"")))) | G12: =IFERROR(IF(B12="","",INDEX(Viðmið!$B$6:$B$10,MATCH(B12,Viðmið!$C$6:$C$10,0))),"") | H12: =IF(OR(E12="",F12=""),"",E12*KVARDI) | I12: =IF(B12="","",IF(ROUND(SUMIF($B$6:$B$205,B12,$E$6:$E$205),4)=ROUND(IFERROR(INDEX(Viðmið!$E$6:$E$10,MATCH(B12,Viðmið!$C$6:$C$10,0)),-1),4),"✓","✗")) | J12: =IF($C12="","",IF($G12="Einstaklingsbundið",IFERROR(IF(INDEX('Undirviðmiðalisti (Lýsigögn)'!F$42:F$58,MATCH($C12,'Undirviðmiðalisti (Lýsigögn)'!$C$42:$C$58,0))="","",INDEX('Undirviðmiðalisti (Lýsigögn)'!F$42:F$58,MATCH($C12,'Undirviðmiðalisti (Lýsigögn)'!$C$42:$C$58,0))),""),IFERROR(IF(INDEX('Undirviðmiðalisti (Lýsigögn)'!F$6:F$41,MATCH($C12,'Undirviðmiðalisti (Lýsigögn)'!$C$6:$C$41,0))="","",INDEX('Undirviðmiðalisti (Lýsigögn)'!F$6:F$41,MATCH($C12,'Undirviðmiðalisti (Lýsigögn)'!$C$6:$C$41,0))),IFERROR(IF(INDEX('Undirviðmiðalisti (Lýsigögn)'!F$42:F$58,MATCH($C12,'Undirviðmiðalisti (Lýsigögn)'!$C$42:$C$58,0))="","",INDEX('Undirviðmiðalisti (Lýsigögn)'!F$42:F$58,MATCH($C12,'Undirviðmiðalisti (Lýsigögn)'!$C$42:$C$58,0))),"")))) | K12: =IF($C12="","",IF($G12="Einstaklingsbundið",IFERROR(IF(INDEX('Undirviðmiðalisti (Lýsigögn)'!G$42:G$58,MATCH($C12,'Undirviðmiðalisti (Lýsigögn)'!$C$42:$C$58,0))="","",INDEX('Undirviðmiðalisti (Lýsigögn)'!G$42:G$58,MATCH($C12,'Undirviðmiðalisti (Lýsigögn)'!$C$42:$C$58,0))),""),IFERROR(IF(INDEX('Undirviðmiðalisti (Lýsigögn)'!G$6:G$41,MATCH($C12,'Undirviðmiðalisti (Lýsigögn)'!$C$6:$C$41,0))="","",INDEX('Undirviðmiðalisti (Lýsigögn)'!G$6:G$41,MATCH($C12,'Undirviðmiðalisti (Lýsigögn)'!$C$6:$C$41,0))),IFERROR(IF(INDEX('Undirviðmiðalisti (Lýsigögn)'!G$42:G$58,MATCH($C12,'Undirviðmiðalisti (Lýsigögn)'!$C$42:$C$58,0))="","",INDEX('Undirviðmiðalisti (Lýsigögn)'!G$42:G$58,MATCH($C12,'Undirviðmiðalisti (Lýsigögn)'!$C$42:$C$58,0))),"")))) | L12: =IF($C12="","",IF($G12="Einstaklingsbundið",IFERROR(IF(INDEX('Undirviðmiðalisti (Lýsigögn)'!H$42:H$58,MATCH($C12,'Undirviðmiðalisti (Lýsigögn)'!$C$42:$C$58,0))="","",INDEX('Undirviðmiðalisti (Lýsigögn)'!H$42:H$58,MATCH($C12,'Undirviðmiðalisti (Lýsigögn)'!$C$42:$C$58,0))),""),IFERROR(IF(INDEX('Undirviðmiðalisti (Lýsigögn)'!H$6:H$41,MATCH($C12,'Undirviðmiðalisti (Lýsigögn)'!$C$6:$C$41,0))="","",INDEX('Undirviðmiðalisti (Lýsigögn)'!H$6:H$41,MATCH($C12,'Undirviðmiðalisti (Lýsigögn)'!$C$6:$C$41,0))),IFERROR(IF(INDEX('Undirviðmiðalisti (Lýsigögn)'!H$42:H$58,MATCH($C12,'Undirviðmiðalisti (Lýsigögn)'!$C$42:$C$58,0))="","",INDEX('Undirviðmiðalisti (Lýsigögn)'!H$42:H$58,MATCH($C12,'Undirviðmiðalisti (Lýsigögn)'!$C$42:$C$58,0))),"")))) | M12: =IF($C12="","",IF($G12="Einstaklingsbundið",IFERROR(IF(INDEX('Undirviðmiðalisti (Lýsigögn)'!I$42:I$58,MATCH($C12,'Undirviðmiðalisti (Lýsigögn)'!$C$42:$C$58,0))="","",INDEX('Undirviðmiðalisti (Lýsigögn)'!I$42:I$58,MATCH($C12,'Undirviðmiðalisti (Lýsigögn)'!$C$42:$C$58,0))),""),IFERROR(IF(INDEX('Undirviðmiðalisti (Lýsigögn)'!I$6:I$41,MATCH($C12,'Undirviðmiðalisti (Lýsigögn)'!$C$6:$C$41,0))="","",INDEX('Undirviðmiðalisti (Lýsigögn)'!I$6:I$41,MATCH($C12,'Undirviðmiðalisti (Lýsigögn)'!$C$6:$C$41,0))),IFERROR(IF(INDEX('Undirviðmiðalisti (Lýsigögn)'!I$42:I$58,MATCH($C12,'Undirviðmiðalisti (Lýsigögn)'!$C$42:$C$58,0))="","",INDEX('Undirviðmiðalisti (Lýsigögn)'!I$42:I$58,MATCH($C12,'Undirviðmiðalisti (Lýsigögn)'!$C$42:$C$58,0))),"")))) | N12: =IF($C12="","",IF($G12="Einstaklingsbundið",IFERROR(IF(INDEX('Undirviðmiðalisti (Lýsigögn)'!J$42:J$58,MATCH($C12,'Undirviðmiðalisti (Lýsigögn)'!$C$42:$C$58,0))="","",INDEX('Undirviðmiðalisti (Lýsigögn)'!J$42:J$58,MATCH($C12,'Undirviðmiðalisti (Lýsigögn)'!$C$42:$C$58,0))),""),IFERROR(IF(INDEX('Undirviðmiðalisti (Lýsigögn)'!J$6:J$41,MATCH($C12,'Undirviðmiðalisti (Lýsigögn)'!$C$6:$C$41,0))="","",INDEX('Undirviðmiðalisti (Lýsigögn)'!J$6:J$41,MATCH($C12,'Undirviðmiðalisti (Lýsigögn)'!$C$6:$C$41,0))),IFERROR(IF(INDEX('Undirviðmiðalisti (Lýsigögn)'!J$42:J$58,MATCH($C12,'Undirviðmiðalisti (Lýsigögn)'!$C$42:$C$58,0))="","",INDEX('Undirviðmiðalisti (Lýsigögn)'!J$42:J$58,MATCH($C12,'Undirviðmiðalisti (Lýsigögn)'!$C$42:$C$58,0))),"")))) | O12: =IF($C12="","",IF($G12="Einstaklingsbundið",IFERROR(IF(INDEX('Undirviðmiðalisti (Lýsigögn)'!K$42:K$58,MATCH($C12,'Undirviðmiðalisti (Lýsigögn)'!$C$42:$C$58,0))="","",INDEX('Undirviðmiðalisti (Lýsigögn)'!K$42:K$58,MATCH($C12,'Undirviðmiðalisti (Lýsigögn)'!$C$42:$C$58,0))),""),IFERROR(IF(INDEX('Undirviðmiðalisti (Lýsigögn)'!K$6:K$41,MATCH($C12,'Undirviðmiðalisti (Lýsigögn)'!$C$6:$C$41,0))="","",INDEX('Undirviðmiðalisti (Lýsigögn)'!K$6:K$41,MATCH($C12,'Undirviðmiðalisti (Lýsigögn)'!$C$6:$C$41,0))),IFERROR(IF(INDEX('Undirviðmiðalisti (Lýsigögn)'!K$42:K$58,MATCH($C12,'Undirviðmiðalisti (Lýsigögn)'!$C$42:$C$58,0))="","",INDEX('Undirviðmiðalisti (Lýsigögn)'!K$42:K$58,MATCH($C12,'Undirviðmiðalisti (Lýsigögn)'!$C$42:$C$58,0))),"")))) | P12: =IF($C12="","",IF($G12="Einstaklingsbundið",IFERROR(IF(INDEX('Undirviðmiðalisti (Lýsigögn)'!L$42:L$58,MATCH($C12,'Undirviðmiðalisti (Lýsigögn)'!$C$42:$C$58,0))="","",INDEX('Undirviðmiðalisti (Lýsigögn)'!L$42:L$58,MATCH($C12,'Undirviðmiðalisti (Lýsigögn)'!$C$42:$C$58,0))),""),IFERROR(IF(INDEX('Undirviðmiðalisti (Lýsigögn)'!L$6:L$41,MATCH($C12,'Undirviðmiðalisti (Lýsigögn)'!$C$6:$C$41,0))="","",INDEX('Undirviðmiðalisti (Lýsigögn)'!L$6:L$41,MATCH($C12,'Undirviðmiðalisti (Lýsigögn)'!$C$6:$C$41,0))),IFERROR(IF(INDEX('Undirviðmiðalisti (Lýsigögn)'!L$42:L$58,MATCH($C12,'Undirviðmiðalisti (Lýsigögn)'!$C$42:$C$58,0))="","",INDEX('Undirviðmiðalisti (Lýsigögn)'!L$42:L$58,MATCH($C12,'Undirviðmiðalisti (Lýsigögn)'!$C$42:$C$58,0))),"")))) | Q12: =IF($C12="","",IF($G12="Einstaklingsbundið",IFERROR(IF(INDEX('Undirviðmiðalisti (Lýsigögn)'!M$42:M$58,MATCH($C12,'Undirviðmiðalisti (Lýsigögn)'!$C$42:$C$58,0))="","",INDEX('Undirviðmiðalisti (Lýsigögn)'!M$42:M$58,MATCH($C12,'Undirviðmiðalisti (Lýsigögn)'!$C$42:$C$58,0))),""),IFERROR(IF(INDEX('Undirviðmiðalisti (Lýsigögn)'!M$6:M$41,MATCH($C12,'Undirviðmiðalisti (Lýsigögn)'!$C$6:$C$41,0))="","",INDEX('Undirviðmiðalisti (Lýsigögn)'!M$6:M$41,MATCH($C12,'Undirviðmiðalisti (Lýsigögn)'!$C$6:$C$41,0))),IFERROR(IF(INDEX('Undirviðmiðalisti (Lýsigögn)'!M$42:M$58,MATCH($C12,'Undirviðmiðalisti (Lýsigögn)'!$C$42:$C$58,0))="","",INDEX('Undirviðmiðalisti (Lýsigögn)'!M$42:M$58,MATCH($C12,'Undirviðmiðalisti (Lýsigögn)'!$C$42:$C$58,0))),""))))
